Workbook

Sheet MASTER BP
B2: TRAFO DISTRIBUSI
C3: Amurang 150 kV | E3: Buroko 150 kV | G3: Botupingge 150 kV | K3: Isimu 150 kV | O3: Kawangkoan 150 kV | U3: Lolak 150 kV | W3: Lopana 150 kV | AA3: Marisa 150 kV | AC3: Otam 150 kV | AG3: Teling 150 kV | AK3: Tanjung Merah 150 kV | AO3: Paniki 150 kV | AS3: Anggrek 150 kV | AU3: Sinsingon 150 kV | AW3: Bitung 70 kV | BC3: Likupang 70 kV | BG3: Ranomuut 70 kV | BO3: Sawangan 70 kV
B4: JAM | C4: Trafo 1 150/20 kV | E4: Trafo 1 150/20 kV | G4: Trafo 1 150/20 kV | I4: Trafo 2 150/20 kV | K4: Trafo 1 150/20 kV | M4: Trafo 2 150/20 kV | O4: Trafo 1 150/20 kV | Q4: Trafo 2 150/20 kV | S4: Trafo 3 150/20 kV | U4: Trafo 1 150/20 kV | W4: Trafo 1 150/20 kV | Y4: Trafo 2 150/20 kV | AA4: Trafo 1 150/20 kV | AC4: Trafo 1 150/20 kV | AE4: Trafo 2 150/20 kV | AG4: Trafo 1 150/20 kV | AI4: Trafo Mobile 1 150/20 kV | AK4: Trafo 1 150/20 kV | AM4: Trafo 2 150/20 kV | AO4: Trafo 1 150/20 kV | AQ4: Trafo 2 150/20 kV | AS4: Trafo 1 150/20 kV | AU4: Trafo 1 150/20 kV | AW4: Trafo 1 70/20 kV | AY4: Trafo 4 70/20 kV | BA4: Trafo 6 70/20 kV | BC4: Trafo 1 70/20 kV | BE4: Trafo 2 70/20 kV | BG4: Trafo 1 70/20 kV | BI4: Trafo 2 70/20 kV | BK4: Trafo 3 70/20 kV | BM4: Trafo 4 70/20 kV | BO4: Trafo 1 70/20 kV | BQ4: Trafo 2 70/20 kV
C5: MW | D5: MVAR | E5: MW | F5: MVAR | G5: MW | H5: MVAR | I5: MW | J5: MVAR | K5: MW | L5: MVAR | M5: MW | N5: MVAR | O5: MW | P5: MVAR | Q5: MW | R5: MVAR | S5: MW | T5: MVAR | U5: MW | V5: MVAR | W5: MW | X5: MVAR | Y5: MW | Z5: MVAR | AA5: MW | AB5: MVAR | AC5: MW | AD5: MVAR | AE5: MW | AF5: MVAR | AG5: MW | AH5: MVAR | AI5: MW | AJ5: MVAR | AK5: MW | AL5: MVAR | AM5: MW | AN5: MVAR | AO5: MW | AP5: MVAR | AQ5: MW | AR5: MVAR | AS5: MW | AT5: MVAR | AU5: MW | AV5: MVAR | AW5: MW | AX5: MVAR | AY5: MW | AZ5: MVAR | BA5: MW | BB5: MVAR | BC5: MW | BD5: MVAR | BE5: MW | BF5: MVAR | BG5: MW | BH5: MVAR | BI5: MW | BJ5: MVAR | BK5: MW | BL5: MVAR | BM5: MW | BN5: MVAR | BO5: MW | BP5: MVAR | BQ5: MW | BR5: MVAR
B7: 0
B8: 0.020833333 | C8: 0 | D8: 0 | E8: 2.8390002 | F8: 0.55500001 | G8: 24.099001 | H8: 7.2660003 | I8: 5.008666 | J8: 0.75908178 | K8: 0 | L8: 0 | M8: 10.771885 | N8: 2.0117941 | O8: 0 | P8: 0 | Q8: 0 | R8: 0 | S8: 9.5929432 | T8: 2.7960136 | U8: 7.3540006 | V8: 1.7980001 | W8: 8.5650005 | X8: 3.2440002 | Y8: 1.8550001 | Z8: 0.46600002 | AA8: 8.434 | AB8: 14.221001 | AC8: 10.142 | AD8: 3.4610002 | AE8: 2.7593424 | AF8: 0.63844395 | AG8: 15.275419 | AH8: 3.3817143 | AI8: 14.360802 | AJ8: 3.4649465 | AK8: 11.841001 | AL8: 3.1330001 | AM8: 5.5327706 | AN8: 1.780388 | AO8: 0 | AP8: 0 | AQ8: 20.866421 | AR8: 6.7013731 | AS8: 6.7340002 | AT8: -1.082 | AU8: 1.8567191 | AV8: 0.4252286 | AW8: 3.2360001 | AX8: -1.202 | AY8: 6.3180003 | AZ8: 4.658 | BA8: 6.8870006 | BB8: 2.8110001 | BC8: 3.2120001 | BD8: 0.77200001 | BE8: 0 | BF8: 0 | BG8: 6.4300003 | BH8: 1.677 | BI8: 3.7480001 | BJ8: 0.54400003 | BK8: 0 | BL8: 0 | BM8: 2.7900002 | BN8: 0.98700005 | BO8: 0 | BP8: 0 | BQ8: 0 | BR8: 0
B9: 0.041666667 | C9: 0 | D9: 0 | E9: 2.7520001 | F9: 0.56800002 | G9: 24.099001 | H9: 7.1600003 | I9: 4.8631463 | J9: 0.7648046 | K9: 0 | L9: 0 | M9: 10.543459 | N9: 2.0151796 | O9: 0 | P9: 0 | Q9: 0 | R9: 0 | S9: 9.2467575 | T9: 2.6883206 | U9: 7.2010002 | V9: 1.7530001 | W9: 8.3630009 | X9: 3.2700002 | Y9: 1.8180001 | Z9: 0.48300001 | AA9: 8.1760006 | AB9: 14.283001 | AC9: 10.142 | AD9: 3.1850002 | AE9: 2.6780725 | AF9: 0.64142907 | AG9: 14.893484 | AH9: 3.3444164 | AI9: 14.050881 | AJ9: 3.4469171 | AK9: 11.488001 | AL9: 3.154 | AM9: 5.385613 | AN9: 1.7157791 | AO9: 0 | AP9: 0 | AQ9: 20.449322 | AR9: 6.6277604 | AS9: 6.7370005 | AT9: -1.257 | AU9: 1.8201985 | AV9: 0.40543649 | AW9: 3.1270001 | AX9: -1.125 | AY9: 6.9280005 | AZ9: 4.7860003 | BA9: 6.8820004 | BB9: 2.8060002 | BC9: 3.1620002 | BD9: 0.76700002 | BE9: 0 | BF9: 0 | BG9: 6.2990003 | BH9: 1.7060001 | BI9: 3.6190002 | BJ9: 0.49600002 | BK9: 0 | BL9: 0 | BM9: 2.7460001 | BN9: 0.98000002 | BO9: 0 | BP9: 0 | BQ9: 0 | BR9: 0
B10: 0.0625 | C10: 0 | D10: 0 | E10: 2.6800001 | F10: 0.54400003 | G10: 23.087002 | H10: 7.1010003 | I10: 4.7084508 | J10: 0.74305254 | K10: 0 | L10: 0 | M10: 10.26515 | N10: 1.9478264 | O10: 0 | P10: 0 | Q10: 0 | R10: 0 | S10: 9.1272058 | T10: 2.6707976 | U10: 7.0200005 | V10: 1.7460001 | W10: 8.217 | X10: 3.2320001 | Y10: 1.7340001 | Z10: 0.47400004 | AA10: 7.9100003 | AB10: 14.337001 | AC10: 10.142 | AD10: 3.1750002 | AE10: 2.5747602 | AF10: 0.59940767 | AG10: 14.518369 | AH10: 3.2766614 | AI10: 13.70819 | AJ10: 3.3940825 | AK10: 11.237 | AL10: 3.0810001 | AM10: 5.3058095 | AN10: 1.6581502 | AO10: 0 | AP10: 0 | AQ10: 19.956411 | AR10: 6.5429125 | AS10: 6.5410004 | AT10: -1.2479999 | AU10: 1.6388093 | AV10: 0.39491338 | AW10: 3.052 | AX10: -1.1040001 | AY10: 7.2040005 | AZ10: 4.8850002 | BA10: 6.6480002 | BB10: 2.786 | BC10: 3.108 | BD10: 0.71000004 | BE10: 0 | BF10: 0 | BG10: 6.1240001 | BH10: 1.705 | BI10: 3.5250001 | BJ10: 0.47900003 | BK10: 0 | BL10: 0 | BM10: 2.72 | BN10: 1.0090001 | BO10: 0 | BP10: 0 | BQ10: 0 | BR10: 0
B11: 0.083333333 | C11: 0 | D11: 0 | E11: 2.6260002 | F11: 0.59400004 | G11: 21.673 | H11: 6.6640005 | I11: 4.5642314 | J11: 0.74335825 | K11: 0 | L11: 0 | M11: 10.09734 | N11: 2.1909618 | O11: 0 | P11: 0 | Q11: 0 | R11: 0 | S11: 8.9743395 | T11: 2.6949501 | U11: 6.9030004 | V11: 1.7880001 | W11: 7.9300003 | X11: 3.2380002 | Y11: 1.6940001 | Z11: 0.48600003 | AA11: 7.7660003 | AB11: 14.526001 | AC11: 9.0780001 | AD11: 3.095 | AE11: 2.5364041 | AF11: 0.64060307 | AG11: 14.170465 | AH11: 3.3878317 | AI11: 13.401606 | AJ11: 3.4836049 | AK11: 10.975 | AL11: 3.0740001 | AM11: 5.2137589 | AN11: 1.7512597 | AO11: 0 | AP11: 0 | AQ11: 19.529572 | AR11: 6.7346163 | AS11: 6.1660004 | AT11: -1.293 | AU11: 1.7782985 | AV11: 0.41780743 | AW11: 3.0900002 | AX11: -1.0070001 | AY11: 6.9280005 | AZ11: 4.8910003 | BA11: 5.3110003 | BB11: 2.1190002 | BC11: 2.9890001 | BD11: 0.69700003 | BE11: 0 | BF11: 0 | BG11: 5.9860001 | BH11: 1.6900001 | BI11: 3.5470002 | BJ11: 0.60600001 | BK11: 0 | BL11: 0 | BM11: 2.6450002 | BN11: 0.94100004 | BO11: 0 | BP11: 0 | BQ11: 0 | BR11: 0
B12: 0.10416667 | C12: 0 | D12: 0 | E12: 2.549 | F12: 0.48400003 | G12: 21.228001 | H12: 6.6670003 | I12: 4.4269719 | J12: 0.72333467 | K12: 0 | L12: 0 | M12: 9.9502068 | N12: 2.080168 | O12: 0 | P12: 0 | Q12: 0 | R12: 0 | S12: 8.8476295 | T12: 2.7261972 | U12: 6.8350005 | V12: 1.7570001 | W12: 7.9680004 | X12: 3.2290001 | Y12: 1.6980001 | Z12: 0.48400003 | AA12: 7.6360002 | AB12: 14.544001 | AC12: 9.0780001 | AD12: 3.0510001 | AE12: 2.4928629 | AF12: 0.65939456 | AG12: 13.973036 | AH12: 3.4275274 | AI12: 13.02952 | AJ12: 3.2074115 | AK12: 10.751 | AL12: 3.1470001 | AM12: 5.1225924 | AN12: 1.7563621 | AO12: 0 | AP12: 0 | AQ12: 19.032902 | AR12: 6.6239667 | AS12: 5.8940001 | AT12: -1.2090003 | AU12: 1.7685564 | AV12: 0.41751871 | AW12: 3.0790002 | AX12: -1.1110001 | AY12: 6.9560003 | AZ12: 4.802 | BA12: 4.73 | BB12: 1.6100001 | BC12: 3.0030003 | BD12: 0.72300005 | BE12: 0 | BF12: 0 | BG12: 5.9100003 | BH12: 1.692 | BI12: 3.5010002 | BJ12: 0.64700001 | BK12: 0 | BL12: 0 | BM12: 2.608 | BN12: 0.95600003 | BO12: 0 | BP12: 0 | BQ12: 0 | BR12: 0
B13: 0.125 | C13: 0 | D13: 0 | E13: 2.5330002 | F13: 0.48000002 | G13: 20.948002 | H13: 6.5700002 | I13: 4.4193158 | J13: 0.72820961 | K13: 0 | L13: 0 | M13: 9.8354759 | N13: 1.9903373 | O13: 0 | P13: 0 | Q13: 0 | R13: 0 | S13: 8.7875547 | T13: 2.6569774 | U13: 6.7630005 | V13: 1.725 | W13: 7.9490004 | X13: 3.2780001 | Y13: 1.71 | Z13: 0.514 | AA13: 7.5580006 | AB13: 14.667001 | AC13: 9.0780001 | AD13: 2.8060002 | AE13: 2.4671328 | AF13: 0.64346719 | AG13: 13.775322 | AH13: 3.3069627 | AI13: 12.848459 | AJ13: 3.1425035 | AK13: 10.771001 | AL13: 3.006 | AM13: 5.0845103 | AN13: 1.712347 | AO13: 0 | AP13: 0 | AQ13: 18.809891 | AR13: 6.5510283 | AS13: 6.0060005 | AT13: -1.4310002 | AU13: 1.754521 | AV13: 0.3943536 | AW13: 3.0410001 | AX13: -1.1140001 | AY13: 6.6140003 | AZ13: 4.651 | BA13: 4.9480004 | BB13: 1.659 | BC13: 2.9720001 | BD13: 0.70600003 | BE13: 0 | BF13: 0 | BG13: 5.8620005 | BH13: 1.6680001 | BI13: 3.3790002 | BJ13: 0.49900001 | BK13: 0 | BL13: 0 | BM13: 2.7170002 | BN13: 0.98300004 | BO13: 0 | BP13: 0 | BQ13: 0 | BR13: 0
B14: 0.14583333 | C14: 0 | D14: 0 | E14: 2.4820001 | F14: 0.43600002 | G14: 20.948002 | H14: 6.4000001 | I14: 4.2959957 | J14: 0.64235491 | K14: 0 | L14: 0 | M14: 9.7518816 | N14: 1.9746023 | O14: 0 | P14: 0 | Q14: 0 | R14: 0 | S14: 8.7261381 | T14: 2.5080845 | U14: 6.6770005 | V14: 1.6650001 | W14: 7.8970003 | X14: 3.0930002 | Y14: 1.682 | Z14: 0.48000002 | AA14: 7.4910002 | AB14: 14.547001 | AC14: 9.0780001 | AD14: 2.8660002 | AE14: 2.4326425 | AF14: 0.57465518 | AG14: 13.416379 | AH14: 3.1200423 | AI14: 12.668158 | AJ14: 3.0219376 | AK14: 10.535001 | AL14: 2.8740001 | AM14: 5.0125461 | AN14: 1.6653734 | AO14: 0 | AP14: 0 | AQ14: 18.44047 | AR14: 6.1693597 | AS14: 5.8440003 | AT14: -1.4170001 | AU14: 1.7390282 | AV14: 0.38644841 | AW14: 2.881 | AX14: -1.1580001 | AY14: 6.9130001 | AZ14: 4.2210002 | BA14: 5.8200002 | BB14: 2.3820002 | BC14: 2.9260001 | BD14: 0.69200003 | BE14: 0 | BF14: 0 | BG14: 5.6680002 | BH14: 1.5530001 | BI14: 3.4320002 | BJ14: 0.53300005 | BK14: 0 | BL14: 0 | BM14: 2.5740001 | BN14: 0.86200005 | BO14: 0 | BP14: 0 | BQ14: 0 | BR14: 0
B15: 0.16666667 | C15: 0 | D15: 0 | E15: 2.4450002 | F15: 0.40300003 | G15: 20.515001 | H15: 6.2250004 | I15: 4.2391434 | J15: 0.63809818 | K15: 0 | L15: 0 | M15: 9.6737404 | N15: 1.8572474 | O15: 0 | P15: 0 | Q15: 0 | R15: 0 | S15: 8.763217 | T15: 2.5199928 | U15: 6.7080002 | V15: 1.6530001 | W15: 7.9190001 | X15: 3.0410001 | Y15: 1.6900001 | Z15: 0.47300002 | AA15: 7.4160004 | AB15: 14.402 | AC15: 9.0780001 | AD15: 2.7 | AE15: 2.434741 | AF15: 0.59232157 | AG15: 13.312897 | AH15: 2.9879708 | AI15: 12.385852 | AJ15: 2.7873337 | AK15: 10.333 | AL15: 2.7740002 | AM15: 4.9529514 | AN15: 1.5321653 | AO15: 0 | AP15: 0 | AQ15: 18.261221 | AR15: 6.0475297 | AS15: 5.6820002 | AT15: -1.5320001 | AU15: 1.7273117 | AV15: 0.36710128 | AW15: 2.7920001 | AX15: -1.1780001 | AY15: 6.7610002 | AZ15: 3.8200002 | BA15: 6.1500001 | BB15: 2.381 | BC15: 2.9620001 | BD15: 0.74200004 | BE15: 0 | BF15: 0 | BG15: 5.6210003 | BH15: 1.4430001 | BI15: 3.4410002 | BJ15: 0.46100003 | BK15: 0 | BL15: 0 | BM15: 2.5300002 | BN15: 0.80700004 | BO15: 0 | BP15: 0 | BQ15: 0 | BR15: 0
B16: 0.1875 | C16: 0 | D16: 0 | E16: 2.4840002 | F16: 0.41600001 | G16: 20.121 | H16: 6.3150005 | I16: 4.2304444 | J16: 0.67094427 | K16: 0 | L16: 0 | M16: 9.7315483 | N16: 1.840243 | O16: 0 | P16: 0 | Q16: 0 | R16: 0 | S16: 8.9648972 | T16: 2.5668252 | U16: 6.7900004 | V16: 1.6520001 | W16: 7.7870002 | X16: 3.0210001 | Y16: 1.6780001 | Z16: 0.46900001 | AA16: 7.4860005 | AB16: 14.551001 | AC16: 9.0780001 | AD16: 2.8260002 | AE16: 2.4862816 | AF16: 0.61645168 | AG16: 13.339547 | AH16: 3.1165674 | AI16: 12.464735 | AJ16: 2.9635088 | AK16: 10.425 | AL16: 2.8530002 | AM16: 5.1504011 | AN16: 1.6257581 | AO16: 0 | AP16: 0 | AQ16: 18.371317 | AR16: 6.2108507 | AS16: 5.6830006 | AT16: -1.5130002 | AU16: 1.7632556 | AV16: 0.38497117 | AW16: 2.8420002 | AX16: -1.154 | AY16: 6.3380003 | AZ16: 4.1290002 | BA16: 6.1090002 | BB16: 2.5400002 | BC16: 2.9440002 | BD16: 0.64600003 | BE16: 0 | BF16: 0 | BG16: 5.7510004 | BH16: 1.5510001 | BI16: 3.4720001 | BJ16: 0.52100003 | BK16: 0 | BL16: 0 | BM16: 2.4840002 | BN16: 0.90100002 | BO16: 0 | BP16: 0 | BQ16: 0 | BR16: 0
B17: 0.20833333 | C17: 0 | D17: 0 | E17: 2.5800002 | F17: 0.42300001 | G17: 20.576 | H17: 6.3350005 | I17: 4.3025422 | J17: 0.67064786 | K17: 0 | L17: 0 | M17: 10.067868 | N17: 1.8545845 | O17: 0 | P17: 0 | Q17: 0 | R17: 0 | S17: 9.3153868 | T17: 2.6440477 | U17: 6.9960003 | V17: 1.6580001 | W17: 7.9710002 | X17: 3.1140001 | Y17: 1.7600001 | Z17: 0.50200003 | AA17: 7.6950002 | AB17: 14.508 | AC17: 9.0780001 | AD17: 2.8440001 | AE17: 2.5751615 | AF17: 0.59368938 | AG17: 13.445988 | AH17: 3.042258 | AI17: 12.909685 | AJ17: 3.1445918 | AK17: 10.213 | AL17: 2.7930002 | AM17: 5.1521816 | AN17: 1.6252061 | AO17: 0 | AP17: 0 | AQ17: 18.64123 | AR17: 6.2363162 | AS17: 5.6910005 | AT17: -1.4320002 | AU17: 1.805517 | AV17: 0.37040225 | AW17: 2.8600001 | AX17: -1.153 | AY17: 6.6210003 | AZ17: 4.0680003 | BA17: 6.2410002 | BB17: 2.6390002 | BC17: 2.9390001 | BD17: 0.56900001 | BE17: 0 | BF17: 0 | BG17: 5.8400002 | BH17: 1.554 | BI17: 3.4540002 | BJ17: 0.48100004 | BK17: 0 | BL17: 0 | BM17: 2.6550002 | BN17: 0.94600004 | BO17: 0 | BP17: 0 | BQ17: 0 | BR17: 0
B18: 0.22916667 | C18: 0 | D18: 0 | E18: 2.6300001 | F18: 0.40100002 | G18: 20.576 | H18: 6.2610002 | I18: 4.2209482 | J18: 0.62776208 | K18: 0 | L18: 0 | M18: 10.04234 | N18: 1.9593581 | O18: 0 | P18: 0 | Q18: 0 | R18: 0 | S18: 9.792449 | T18: 2.6920829 | U18: 7.2290006 | V18: 1.7360001 | W18: 7.7350001 | X18: 3.0040002 | Y18: 1.7290001 | Z18: 0.41300002 | AA18: 7.7430005 | AB18: 14.512001 | AC18: 9.0780001 | AD18: 2.8690002 | AE18: 2.6661227 | AF18: 0.61267674 | AG18: 13.688897 | AH18: 3.0593879 | AI18: 13.453328 | AJ18: 3.2165356 | AK18: 10.13 | AL18: 2.7270002 | AM18: 5.2549176 | AN18: 1.8030002 | AO18: 0 | AP18: 0 | AQ18: 19.144003 | AR18: 6.3390169 | AS18: 5.5599999 | AT18: -1.1789999 | AU18: 1.8779886 | AV18: 0.38113302 | AW18: 2.8840001 | AX18: -1.154 | AY18: 7.1090002 | AZ18: 4.1480002 | BA18: 6.3300004 | BB18: 2.5860002 | BC18: 3.0050001 | BD18: 0.61400002 | BE18: 0 | BF18: 0 | BG18: 6.0200005 | BH18: 1.5580001 | BI18: 3.5540001 | BJ18: 0.509 | BK18: 0 | BL18: 0 | BM18: 2.605 | BN18: 0.89700001 | BO18: 0 | BP18: 0 | BQ18: 0 | BR18: 0
B19: 0.25 | C19: 0 | D19: 0 | E19: 2.6830001 | F19: 0.51300001 | G19: 20.045 | H19: 6.4420004 | I19: 4.1840277 | J19: 0.71338195 | K19: 0 | L19: 0 | M19: 10.07003 | N19: 2.2455716 | O19: 0 | P19: 0 | Q19: 0 | R19: 0 | S19: 10.268228 | T19: 3.0460074 | U19: 7.3040004 | V19: 2.0150001 | W19: 8.2150002 | X19: 3.1160002 | Y19: 1.728 | Z19: 0.46200001 | AA19: 7.6880002 | AB19: 14.549001 | AC19: 9.0780001 | AD19: 2.9840002 | AE19: 2.7588053 | AF19: 0.6964528 | AG19: 13.615909 | AH19: 3.0896268 | AI19: 13.731799 | AJ19: 3.4903235 | AK19: 9.9980001 | AL19: 2.776 | AM19: 5.1194048 | AN19: 1.8170884 | AO19: 0 | AP19: 0 | AQ19: 19.077995 | AR19: 6.4147673 | AS19: 5.4310002 | AT19: -1.2720001 | AU19: 1.901943 | AV19: 0.35984936 | AW19: 2.7900002 | AX19: -1.2040001 | AY19: 6.9490004 | AZ19: 4.1090002 | BA19: 5.9800005 | BB19: 2.444 | BC19: 3.0680001 | BD19: 0.65000004 | BE19: 0 | BF19: 0 | BG19: 6.1900001 | BH19: 1.6760001 | BI19: 3.5990002 | BJ19: 0.52900004 | BK19: 0 | BL19: 0 | BM19: 2.6530001 | BN19: 0.96500003 | BO19: 0 | BP19: 0 | BQ19: 0 | BR19: 0
... B60: 1 | C60: 0 | D60: 0 | E60: 0 | F60: 0 | G60: 0 | H60: 0 | I60: 0 | J60: 0 | K60: 0 | L60: 0 | M60: 0 | N60: 0 | O60: 0 | P60: 0 | Q60: 0 | R60: 0 | S60: 0 | T60: 0 | U60: 0 | V60: 0 | W60: 0 | X60: 0 | Y60: 0 | Z60: 0 | AA60: 0 | AB60: 0 | AC60: 0 | AD60: 0 | AE60: 0 | AF60: 0 | AG60: 0 | AH60: 0 | AI60: 0 | AJ60: 0 | AK60: 0 | AL60: 0 | AM60: 0 | AN60: 0 | AO60: 0 | AP60: 0 | AQ60: 0 | AR60: 0 | AS60: 0 | AT60: 0 | AU60: 0 | AV60: 0 | AW60: 0 | AX60: 0 | AY60: 0 | AZ60: 0 | BA60: 0 | BB60: 0 | BC60: 0 | BD60: 0 | BE60: 0 | BF60: 0 | BG60: 0 | BH60: 0 | BI60: 0 | BJ60: 0 | BK60: 0 | BL60: 0 | BM60: 0 | BN60: 0 | BO60: 0 | BP60: 0 | BQ60: 0 | BR60: 0
A61: BP SIANG
A62: max | C62: =MAX(C23:C39) | D62: =INDEX(D23:D39,MATCH(C63,$B23:$B39,0)) | E62: =MAX(E23:E39) | F62: =INDEX(F23:F39,MATCH(E63,$B$23:$B$39,0)) | G62: =MAX(G23:G39) | H62: =INDEX(H23:H39,MATCH(G63,$B$23:$B$39,0)) | I62: =MAX(I23:I39) | J62: =INDEX(J23:J39,MATCH(I63,$B$23:$B$39,0)) | K62: =MAX(K23:K39) | L62: =INDEX(L23:L39,MATCH(K63,$B$23:$B$39,0)) | M62: =MAX(M23:M39) | N62: =INDEX(N23:N39,MATCH(M63,$B$23:$B$39,0)) | O62: =MAX(O23:O39) | P62: =INDEX(P23:P39,MATCH(O63,$B$23:$B$39,0)) | Q62: =MAX(Q23:Q39) | R62: =INDEX(R23:R39,MATCH(Q63,$B$23:$B$39,0)) | S62: =MAX(S23:S39) | T62: =INDEX(T23:T39,MATCH(S63,$B$23:$B$39,0)) | U62: =MAX(U23:U39) | V62: =INDEX(V23:V39,MATCH(U63,$B$23:$B$39,0)) | W62: =MAX(W23:W39) | X62: =INDEX(X23:X39,MATCH(W63,$B$23:$B$39,0)) | Y62: =MAX(Y23:Y39) | Z62: =INDEX(Z23:Z39,MATCH(Y63,$B$23:$B$39,0)) | AA62: =MAX(AA$23:AA$39) | AB62: =INDEX(AB23:AB39,MATCH(AA63,$B$23:$B$39,0)) | AC62: =MAX(AC23:AC39) | AD62: =INDEX(AD23:AD39,MATCH(AC63,$B$23:$B$39,0)) | AE62: =MAX(AE23:AE39) | AF62: =INDEX(AF23:AF39,MATCH(AE63,$B$23:$B$39,0)) | AG62: =MAX(AG23:AG39) | AH62: =INDEX(AH23:AH39,MATCH(AG63,$B$23:$B$39,0)) | AI62: =MAX(AI23:AI39) | AJ62: =INDEX(AJ23:AJ39,MATCH(AI63,$B$23:$B$39,0)) | AK62: =MAX(AK23:AK39) | AL62: =INDEX(AL23:AL39,MATCH(AK63,$B$23:$B$39,0)) | AM62: =MAX(AM23:AM39) | AN62: =INDEX(AN23:AN39,MATCH(AM63,$B$23:$B$39,0)) | AO62: =MAX(AO23:AO39) | AP62: =INDEX(AP23:AP39,MATCH(AO63,$B$23:$B$39,0)) | AQ62: =MAX(AQ23:AQ39) | AR62: =INDEX(AR23:AR39,MATCH(AQ63,$B$23:$B$39,0)) | AS62: =MAX(AS23:AS39) | AT62: =INDEX(AT23:AT39,MATCH(AS63,$B$23:$B$39,0)) | AU62: =MAX(AU23:AU39) | AV62: =INDEX(AV23:AV39,MATCH(AU63,$B$23:$B$39,0)) | AW62: =MAX(AW23:AW39) | AX62: =INDEX(AX23:AX39,MATCH(AW63,$B$23:$B$39,0)) | AY62: =MAX(AY23:AY39) | AZ62: =INDEX(AZ23:AZ39,MATCH(AY63,$B$23:$B$39,0)) | BA62: =MAX(BA23:BA39) | BB62: =INDEX(BB23:BB39,MATCH(BA63,$B$23:$B$39,0)) | BC62: =MAX(BC23:BC39) | BD62: =INDEX(BD23:BD39,MATCH(BC63,$B$23:$B$39,0)) | BE62: =MAX(BE23:BE39) | BF62: =INDEX(BF23:BF39,MATCH(BE63,$B$23:$B$39,0)) | BG62: =MAX(BG23:BG39) | BH62: =INDEX(BH23:BH39,MATCH(BG63,$B$23:$B$39,0)) | BI62: =MAX(BI23:BI39) | BJ62: =INDEX(BJ23:BJ39,MATCH(BI63,$B$23:$B$39,0)) | BK62: =MAX(BK23:BK39) | BL62: =INDEX(BL23:BL39,MATCH(BK63,$B$23:$B$39,0)) | BM62: =MAX(BM23:BM39) | BN62: =INDEX(BN23:BN39,MATCH(BM63,$B$23:$B$39,0)) | BO62: =MAX(BO23:BO39) | BP62: =INDEX(BP23:BP39,MATCH(BO63,$B$23:$B$39,0)) | BQ62: =MAX(BQ23:BQ39) | BR62: =INDEX(BR23:BR39,MATCH(BQ63,$B$23:$B$39,0))
A63: time | C63: =INDEX($B23:$B39,MATCH(C62,C23:C39,0)) | E63: =INDEX($B$23:$B$39,MATCH(E62,E23:E39,0)) | G63: =INDEX($B$23:$B$39,MATCH(G62,G23:G39,0)) | I63: =INDEX($B$23:$B$39,MATCH(I62,I23:I39,0)) | K63: =INDEX($B$23:$B$39,MATCH(K62,K23:K39,0)) | M63: =INDEX($B$23:$B$39,MATCH(M62,M23:M39,0)) | O63: =INDEX($B$23:$B$39,MATCH(O62,O23:O39,0)) | Q63: =INDEX($B$23:$B$39,MATCH(Q62,Q23:Q39,0)) | S63: =INDEX($B$23:$B$39,MATCH(S62,S23:S39,0)) | U63: =INDEX($B$23:$B$39,MATCH(U62,U23:U39,0)) | W63: =INDEX($B$23:$B$39,MATCH(W62,W23:W39,0)) | Y63: =INDEX($B$23:$B$39,MATCH(Y62,Y23:Y39,0)) | AA63: =INDEX($B$23:$B$39,MATCH(AA62,AA23:AA39,0)) | AC63: =INDEX($B$23:$B$39,MATCH(AC62,AC23:AC39,0)) | AE63: =INDEX($B$23:$B$39,MATCH(AE62,AE23:AE39,0)) | AG63: =INDEX($B$23:$B$39,MATCH(AG62,AG23:AG39,0)) | AI63: =INDEX($B$23:$B$39,MATCH(AI62,AI23:AI39,0)) | AK63: =INDEX($B$23:$B$39,MATCH(AK62,AK23:AK39,0)) | AM63: =INDEX($B$23:$B$39,MATCH(AM62,AM23:AM39,0)) | AO63: =INDEX($B$23:$B$39,MATCH(AO62,AO23:AO39,0)) | AQ63: =INDEX($B$23:$B$39,MATCH(AQ62,AQ23:AQ39,0)) | AS63: =INDEX($B$23:$B$39,MATCH(AS62,AS23:AS39,0)) | AU63: =INDEX($B$23:$B$39,MATCH(AU62,AU23:AU39,0)) | AW63: =INDEX($B$23:$B$39,MATCH(AW62,AW23:AW39,0)) | AY63: =INDEX($B$23:$B$39,MATCH(AY62,AY23:AY39,0)) | BA63: =INDEX($B$23:$B$39,MATCH(BA62,BA23:BA39,0)) | BC63: =INDEX($B$23:$B$39,MATCH(BC62,BC23:BC39,0)) | BE63: =INDEX($B$23:$B$39,MATCH(BE62,BE23:BE39,0)) | BG63: =INDEX($B$23:$B$39,MATCH(BG62,BG23:BG39,0)) | BI63: =INDEX($B$23:$B$39,MATCH(BI62,BI23:BI39,0)) | BK63: =INDEX($B$23:$B$39,MATCH(BK62,BK23:BK39,0)) | BM63: =INDEX($B$23:$B$39,MATCH(BM62,BM23:BM39,0)) | BO63: =INDEX($B$23:$B$39,MATCH(BO62,BO23:BO39,0)) | BQ63: =INDEX($B$23:$B$39,MATCH(BQ62,BQ23:BQ39,0))
A64: average | C64: =AVERAGE(C$23:C$39) | D64: =AVERAGE(D$23:D$39) | E64: =AVERAGE(E$23:E$39) | F64: =AVERAGE(F$23:F$39) | G64: =AVERAGE(G$23:G$39) | H64: =AVERAGE(H$23:H$39) | I64: =AVERAGE(I$23:I$39) | J64: =AVERAGE(J$23:J$39) | ... BR64: =AVERAGE(BR$23:BR$39)
A66: BP MALAM
A67: max | C67: =MAX(C$40:C$56) | D67: =INDEX(D40:D56,MATCH(C68,$B40:$B56,0)) | E67: =MAX(E40:E56) | F67: =INDEX(F40:F56,MATCH(E68,$B40:$B56,0)) | G67: =MAX(G40:G56) | H67: =INDEX(H40:H56,MATCH(G68,$B40:$B56,0)) | I67: =MAX(I40:I56) | J67: =INDEX(J40:J56,MATCH(I68,$B40:$B56,0)) | K67: =MAX(K40:K56) | L67: =INDEX(L40:L56,MATCH(K68,$B40:$B56,0)) | M67: =MAX(M40:M56) | N67: =INDEX(N40:N56,MATCH(M68,$B40:$B56,0)) | O67: =MAX(O40:O56) | P67: =INDEX(P40:P56,MATCH(O68,$B40:$B56,0)) | Q67: =MAX(Q40:Q56) | R67: =INDEX(R40:R56,MATCH(Q68,$B40:$B56,0)) | S67: =MAX(S40:S56) | T67: =INDEX(T40:T56,MATCH(S68,$B40:$B56,0)) | U67: =MAX(U40:U56) | V67: =INDEX(V40:V56,MATCH(U68,$B40:$B56,0)) | W67: =MAX(W40:W56) | X67: =INDEX(X40:X56,MATCH(W68,$B40:$B56,0)) | Y67: =MAX(Y40:Y56) | Z67: =INDEX(Z40:Z56,MATCH(Y68,$B40:$B56,0)) | AA67: =MAX(AA40:AA56) | AB67: =INDEX(AB40:AB56,MATCH(AA68,$B40:$B56,0)) | AC67: =MAX(AC40:AC56) | AD67: =INDEX(AD40:AD56,MATCH(AC68,$B40:$B56,0)) | AE67: =MAX(AE40:AE56) | AF67: =INDEX(AF40:AF56,MATCH(AE68,$B40:$B56,0)) | AG67: =MAX(AG40:AG56) | AH67: =INDEX(AH40:AH56,MATCH(AG68,$B40:$B56,0)) | AI67: =MAX(AI40:AI56) | AJ67: =INDEX(AJ40:AJ56,MATCH(AI68,$B40:$B56,0)) | AK67: =MAX(AK40:AK56) | AL67: =INDEX(AL40:AL56,MATCH(AK68,$B40:$B56,0)) | AM67: =MAX(AM40:AM56) | AN67: =INDEX(AN40:AN56,MATCH(AM68,$B40:$B56,0)) | AO67: =MAX(AO40:AO56) | AP67: =INDEX(AP40:AP56,MATCH(AO68,$B40:$B56,0)) | AQ67: =MAX(AQ40:AQ56) | AR67: =INDEX(AR40:AR56,MATCH(AQ68,$B40:$B56,0)) | AS67: =MAX(AS40:AS56) | AT67: =INDEX(AT40:AT56,MATCH(AS68,$B40:$B56,0)) | AU67: =MAX(AU40:AU56) | AV67: =INDEX(AV40:AV56,MATCH(AU68,$B40:$B56,0)) | AW67: =MAX(AW40:AW56) | AX67: =INDEX(AX40:AX56,MATCH(AW68,$B40:$B56,0)) | AY67: =MAX(AY40:AY56) | AZ67: =INDEX(AZ40:AZ56,MATCH(AY68,$B40:$B56,0)) | BA67: =MAX(BA40:BA56) | BB67: =INDEX(BB40:BB56,MATCH(BA68,$B40:$B56,0)) | BC67: =MAX(BC40:BC56) | BD67: =INDEX(BD40:BD56,MATCH(BC68,$B40:$B56,0)) | BE67: =MAX(BE40:BE56) | BF67: =INDEX(BF40:BF56,MATCH(BE68,$B40:$B56,0)) | BG67: =MAX(BG40:BG56) | BH67: =INDEX(BH40:BH56,MATCH(BG68,$B40:$B56,0)) | BI67: =MAX(BI40:BI56) | BJ67: =INDEX(BJ40:BJ56,MATCH(BI68,$B40:$B56,0)) | BK67: =MAX(BK40:BK56) | BL67: =INDEX(BL40:BL56,MATCH(BK68,$B40:$B56,0)) | BM67: =MAX(BM40:BM56) | BN67: =INDEX(BN40:BN56,MATCH(BM68,$B40:$B56,0)) | BO67: =MAX(BO40:BO56) | BP67: =INDEX(BP40:BP56,MATCH(BO68,$B40:$B56,0)) | BQ67: =MAX(BQ40:BQ56) | BR67: =INDEX(BR40:BR56,MATCH(BQ68,$B40:$B56,0))
A68: time | C68: =INDEX($B40:$B56,MATCH(C67,C40:C56,0)) | E68: =INDEX($B40:$B56,MATCH(E67,E40:E56,0)) | G68: =INDEX($B40:$B56,MATCH(G67,G40:G56,0)) | I68: =INDEX($B40:$B56,MATCH(I67,I40:I56,0)) | K68: =INDEX($B40:$B56,MATCH(K67,K40:K56,0)) | M68: =INDEX($B40:$B56,MATCH(M67,M40:M56,0)) | O68: =INDEX($B40:$B56,MATCH(O67,O40:O56,0)) | Q68: =INDEX($B40:$B56,MATCH(Q67,Q40:Q56,0)) | S68: =INDEX($B40:$B56,MATCH(S67,S40:S56,0)) | U68: =INDEX($B40:$B56,MATCH(U67,U40:U56,0)) | W68: =INDEX($B40:$B56,MATCH(W67,W40:W56,0)) | Y68: =INDEX($B40:$B56,MATCH(Y67,Y40:Y56,0)) | AA68: =INDEX($B40:$B56,MATCH(AA67,AA40:AA56,0)) | AC68: =INDEX($B40:$B56,MATCH(AC67,AC40:AC56,0)) | AE68: =INDEX($B40:$B56,MATCH(AE67,AE40:AE56,0)) | AG68: =INDEX($B40:$B56,MATCH(AG67,AG40:AG56,0)) | AI68: =INDEX($B40:$B56,MATCH(AI67,AI40:AI56,0)) | AK68: =INDEX($B40:$B56,MATCH(AK67,AK40:AK56,0)) | AM68: =INDEX($B40:$B56,MATCH(AM67,AM40:AM56,0)) | AO68: =INDEX($B40:$B56,MATCH(AO67,AO40:AO56,0)) | AQ68: =INDEX($B40:$B56,MATCH(AQ67,AQ40:AQ56,0)) | AS68: =INDEX($B40:$B56,MATCH(AS67,AS40:AS56,0)) | AU68: =INDEX($B40:$B56,MATCH(AU67,AU40:AU56,0)) | AW68: =INDEX($B40:$B56,MATCH(AW67,AW40:AW56,0)) | AY68: =INDEX($B40:$B56,MATCH(AY67,AY40:AY56,0)) | BA68: =INDEX($B40:$B56,MATCH(BA67,BA40:BA56,0)) | BC68: =INDEX($B40:$B56,MATCH(BC67,BC40:BC56,0)) | BE68: =INDEX($B40:$B56,MATCH(BE67,BE40:BE56,0)) | BG68: =INDEX($B40:$B56,MATCH(BG67,BG40:BG56,0)) | BI68: =INDEX($B40:$B56,MATCH(BI67,BI40:BI56,0)) | BK68: =INDEX($B40:$B56,MATCH(BK67,BK40:BK56,0)) | BM68: =INDEX($B40:$B56,MATCH(BM67,BM40:BM56,0)) | BO68: =INDEX($B40:$B56,MATCH(BO67,BO40:BO56,0)) | BQ68: =INDEX($B40:$B56,MATCH(BQ67,BQ40:BQ56,0))
A69: average | C69: =AVERAGE(C$40:C$56) | D69: =AVERAGE(D$40:D$56) | E69: =AVERAGE(E$40:E$56) | F69: =AVERAGE(F$40:F$56) | G69: =AVERAGE(G$40:G$56) | H69: =AVERAGE(H$40:H$56) | I69: =AVERAGE(I$40:I$56) | J69: =AVERAGE(J$40:J$56) | ... BR69: =AVERAGE(BR$40:BR$56)
B73: MW MVAR 70KV LINE TRANSMISSION
C74: G I RANOMUUT | K74: G I BITUNG | S74: G I LIKUPANG | W74: G I SAWANGAN | AQ74: PLTA TANGGARI 1 | AU74: PLTA TANGGARI 2 | AY74: PLTA TONSEALAMA | BC74: G I TONSEALAMA | BK74: G I TELING | BS74: G I TASIKRIA | BW74: G I TOMOHON 70 KV | CI74: PT MSM 70 KV
B75: JAM | C75: TELING | E75: TELING | G75: SAWANGAN | I75: SAWANGAN | K75: SAWANGAN | M75: SAWANGAN | O75: MSM | Q75: LIKUPANG | S75: MSM | U75: BITUNG | W75: PLTA TANGGARI 1 | Y75: PLTA TANGGARI 1 | AA75: TONSEALAMA | AC75: TONSEALAMA | AE75: BITUNG | AG75: BITUNG | AI75: RANOMUUT | AK75: RANOMUUT | AM75: PLTA TANGGARI 2 | AO75: PLTA TANGGARI 2 | AQ75: SAWANGAN | AS75: SAWANGAN | AU75: SAWANGAN | AW75: SAWANGAN | AY75: GI TONSEALAMA | BA75: GI TONSEALAMA | BC75: SAWANGAN | BE75: SAWANGAN | BG75: TOMOHON | BI75: TOMOHON | BK75: TOMOHON | BM75: TOMOHON | BO75: RANOMUUT | BQ75: RANOMUUT | BS75: TOMOHON | BU75: TOMOHON | BW75: TELING | BY75: TELING | CA75: TONSEALAMA | CC75: TONSEALAMA | CE75: TASIKRIA | CG75: TASIKRIA | CI75: BITUNG | CK75: LIKUPANG
C76: LINE 1 | E76: LINE 2 | G76: LINE 1 | I76: LINE 2 | K76: LINE 1 | M76: LINE 2 | O76: LINE 1 | Q76: LINE 1 | S76: LINE 1 | U76: LINE 1 | W76: LINE 1 | Y76: LINE 2 | AA76: LINE 1 | AC76: LINE 2 | AE76: LINE 1 | AG76: LINE 2 | AI76: LINE 1 | AK76: LINE 2 | AM76: LINE 1 | AO76: LINE 2 | AQ76: LINE 1 | AS76: LINE 2 | AU76: LINE 1 | AW76: LINE 2 | AY76: LINE 1 | BA76: LINE 2 | BC76: LINE 1 | BE76: LINE 2 | BG76: LINE 1 | BI76: LINE 2 | BK76: LINE 1 | BM76: LINE 2 | BO76: LINE 1 | BQ76: LINE 2 | BS76: LINE 1 | BU76: LINE 2 | BW76: LINE 1 | BY76: LINE 2 | CA76: LINE 1 | CC76: LINE 2 | CE76: LINE 1 | CG76: LINE 2 | CI76: LINE 1 | CK76: LINE 2
C77: MW | D77: MVAR | E77: MW | F77: MVAR | G77: MW | H77: MVAR | I77: MW | J77: MVAR | K77: MW | L77: MVAR | M77: MW | N77: MVAR | O77: MW | P77: MVAR | Q77: MW | R77: MVAR | S77: MW | T77: MVAR | U77: MW | V77: MVAR | W77: MW | X77: MVAR | Y77: MW | Z77: MVAR | AA77: MW | AB77: MVAR | AC77: MW | AD77: MVAR | AE77: MW | AF77: MVAR | AG77: MW | AH77: MVAR | AI77: MW | AJ77: MVAR | AK77: MW | AL77: MVAR | AM77: MW | AN77: MVAR | AO77: MW | AP77: MVAR | AQ77: MW | AR77: MVAR | AS77: MW | AT77: MVAR | AU77: MW | AV77: MVAR | AW77: MW | AX77: MVAR | AY77: MW | AZ77: MVAR | BA77: MW | BB77: MVAR | BC77: MW | BD77: MVAR | BE77: MW | BF77: MVAR | BG77: MW | BH77: MVAR | BI77: MW | BJ77: MVAR | BK77: MW | BL77: MVAR | BM77: MW | BN77: MVAR | BO77: MW | BP77: MVAR | BQ77: MW | BR77: MVAR | BS77: MW | BT77: MVAR | BU77: MW | BV77: MVAR | BW77: MW | BX77: MVAR | BY77: MW | BZ77: MVAR | CA77: MW | CB77: MVAR | CC77: MW | CD77: MVAR | CE77: MW | CF77: MVAR | CG77: MW | CH77: MVAR | CI77: MW | CJ77: MVAR | CK77: MW | CL77: MVAR
B78: 0
B79: 0.020833333 | C79: -12.175 | D79: -2.0150001 | E79: -11.661 | F79: -1.223 | G79: 0.96300006 | H79: -1.4770001 | I79: 0.96400005 | J79: -1.4710001 | K79: -17.488001 | L79: 1.9160001 | M79: -18.473001 | N79: 0.85200006 | O79: 9.46 | P79: -6.3570004 | Q79: 6.6320004 | R79: -7.4980001 | S79: 3.4900002 | T79: 10.219001 | U79: -6.7210002 | V79: 7.3280005 | W79: 0.001 | X79: -0.039000001 | Y79: -6.9920001 | Z79: -1.1850001 | AA79: -13.461 | AB79: -0.56900001 | AC79: -13.316001 | AD79: -0.47200003 | AE79: 11.905001 | AF79: -1.016 | AG79: 18.865002 | AH79: -0.14600001 | AI79: -0.91800004 | AJ79: 1.2130001 | AK79: -0.92500007 | AL79: 1.25 | AM79: 0 | AN79: 0 | AO79: -3.3329999 | AP79: -0.38100001 | AQ79: 0 | AR79: 0 | AS79: 0.115 | AT79: 0.014 | AU79: 2.2440002 | AV79: 0.13500001 | AW79: 2.227 | AX79: 0.17 | AY79: 0 | AZ79: 0 | BA79: 2.0180001 | BB79: 1.6625488 | BC79: 14.211 | BD79: 3.8420002 | BE79: 14.340001 | BF79: 3.8540001 | BG79: -12.381001 | BH79: -3.6850002 | BI79: -12.362 | BJ79: -3.7110002 | BK79: -10.734 | BL79: -0.97800004 | BM79: -10.721001 | BN79: -0.96800005 | BO79: 12.126 | BP79: 2.079 | BQ79: 11.523 | BR79: 0.90899998 | BS79: -1.927 | BT79: -0.43900001 | BU79: -1.9330001 | BV79: -0.44500002 | BW79: 10.903001 | BX79: 0.82500005 | BY79: 10.925 | BZ79: 0.79500002 | CA79: 13.312 | CB79: 0.583 | CC79: 13.458 | CD79: 0.54400003 | CE79: 2.0370002 | CF79: 0.15000001 | CG79: 1.9650002 | CH79: 0.14300001 | CI79: -9.6282272 | CJ79: 6.1668425 | CK79: -6.012393 | CL79: -10.217578
B80: 0.041666667 | C80: -11.945001 | D80: -1.9820001 | E80: -11.429001 | F80: -1.2080001 | G80: 1.0270001 | H80: -1.4250001 | I80: 1.067 | J80: -1.4490001 | K80: -17.479 | L80: 1.9510001 | M80: -18.597 | N80: 0.82500005 | O80: 9.3950005 | P80: -6.3960004 | Q80: 6.5100002 | R80: -7.5490003 | S80: 3.4190001 | T80: 10.248 | U80: -6.5890002 | V80: 7.3820004 | W80: 0.001 | X80: -0.038000003 | Y80: -6.9690003 | Z80: -1.115 | AA80: -13.296 | AB80: -0.50300002 | AC80: -13.264001 | AD80: -0.43600002 | AE80: 11.995001 | AF80: -1.0250001 | AG80: 18.973001 | AH80: -0.12400001 | AI80: -1.079 | AJ80: 1.2010001 | AK80: -1.072 | AL80: 1.2370001 | AM80: 0 | AN80: 0 | AO80: -3.3930001 | AP80: -0.477 | AQ80: 0 | AR80: 0 | AS80: 0.10700001 | AT80: 0.017000001 | AU80: 2.2360001 | AV80: 0.18100001 | AW80: 2.2680001 | AX80: 0.2 | AY80: 0 | AZ80: 0 | BA80: 1.9910001 | BB80: 1.6625488 | BC80: 14.211 | BD80: 3.8420002 | BE80: 14.340001 | BF80: 3.8540001 | BG80: -12.381001 | BH80: -3.6850002 | BI80: -12.362 | BJ80: -3.7110002 | BK80: -10.514001 | BL80: -0.91200006 | BM80: -10.509001 | BN80: -0.91200006 | BO80: 11.858001 | BP80: 2.0510001 | BQ80: 11.352 | BR80: 0.90899998 | BS80: -1.8560001 | BT80: -0.41200003 | BU80: -1.8790001 | BV80: -0.42500001 | BW80: 10.678 | BX80: 0.76200002 | BY80: 10.726001 | BZ80: 0.74000001 | CA80: 13.285001 | CB80: 0.57500005 | CC80: 13.397 | CD80: 0.48300001 | CE80: 1.9670001 | CF80: 0.13600001 | CG80: 1.8970001 | CH80: 0.12400001 | CI80: -9.6282272 | CJ80: 6.2117772 | CK80: -6.012393 | CL80: -10.213326
B81: 0.0625 | C81: -11.762 | D81: -2.0020001 | E81: -11.287001 | F81: -1.217 | G81: 1.0890001 | H81: -1.4590001 | I81: 1.082 | J81: -1.4230001 | K81: -17.353001 | L81: 1.9910001 | M81: -18.346001 | N81: 0.91600007 | O81: 9.309 | P81: -6.4740005 | Q81: 6.4770002 | R81: -7.6130004 | S81: 3.3640001 | T81: 10.295 | U81: -6.4380002 | V81: 7.5080004 | W81: 0.001 | X81: -0.039000001 | Y81: -7.0240002 | Z81: -1.0710001 | AA81: -13.128 | AB81: -0.43100002 | AC81: -12.995001 | AD81: -0.32900003 | AE81: 11.917001 | AF81: -1.057 | AG81: 18.695002 | AH81: -0.266 | AI81: -1.067 | AJ81: 1.2080001 | AK81: -1.0350001 | AL81: 1.2190001 | AM81: 0 | AN81: 0 | AO81: -3.3540001 | AP81: -0.426 | AQ81: 0 | AR81: 0 | AS81: 0.11300001 | AT81: 0.019000001 | AU81: 2.2690001 | AV81: 0.16900001 | AW81: 2.2710001 | AX81: 0.193 | AY81: 0 | AZ81: 0 | BA81: 2.0180001 | BB81: 1.6625488 | BC81: 14.211 | BD81: 3.8420002 | BE81: 14.340001 | BF81: 3.8540001 | BG81: -12.381001 | BH81: -3.6850002 | BI81: -12.362 | BJ81: -3.7110002 | BK81: -10.355 | BL81: -0.85200006 | BM81: -10.334001 | BN81: -0.82600003 | BO81: 11.685 | BP81: 2.0610001 | BQ81: 11.115 | BR81: 0.95100003 | BS81: -1.83 | BT81: -0.43300003 | BU81: -1.8440001 | BV81: -0.44900003 | BW81: 10.517 | BX81: 0.69100004 | BY81: 10.530001 | BZ81: 0.65500003 | CA81: 13.074 | CB81: 0.51000005 | CC81: 13.154 | CD81: 0.42700002 | CE81: 1.9380001 | CF81: 0.134 | CG81: 1.863 | CH81: 0.123 | CI81: -9.6282272 | CJ81: 6.3085752 | CK81: -6.012393 | CL81: -10.276577
B82: 0.083333333 | C82: -10.954 | D82: -1.9460001 | E82: -10.559001 | F82: -1.273 | G82: 0.551 | H82: -1.4560001 | I82: 0.56400001 | J82: -1.5350001 | K82: -16.399 | L82: 2.1860001 | M82: -17.368 | N82: 1.1910001 | O82: 9.0950003 | P82: -6.4980001 | Q82: 6.2860003 | R82: -7.6440005 | S82: 3.3650002 | T82: 10.313001 | U82: -6.3010001 | V82: 7.4990005 | W82: -0.0020000001 | X82: -0.039000001 | Y82: -7.0300002 | Z82: -1.011 | AA82: -12.482 | AB82: -0.27100003 | AC82: -12.362 | AD82: -0.18200001 | AE82: 11.306001 | AF82: -1.2460001 | AG82: 17.698 | AH82: -0.60700005 | AI82: -0.537 | AJ82: 1.2190001 | AK82: -0.59300005 | AL82: 1.2620001 | AM82: 0 | AN82: 0 | AO82: -3.339 | AP82: -0.384 | AQ82: 0 | AR82: 0 | AS82: 0.11300001 | AT82: 0.022000002 | AU82: 2.2210002 | AV82: 0.15300001 | AW82: 2.2450001 | AX82: 0.17600001 | AY82: 0 | AZ82: 0 | BA82: 2.2080002 | BB82: 1.6625488 | BC82: 14.211 | BD82: 3.8420002 | BE82: 14.340001 | BF82: 3.8540001 | BG82: -12.381001 | BH82: -3.6850002 | BI82: -12.362 | BJ82: -3.7110002 | BK82: -10.065001 | BL82: -0.86700004 | BM82: -10.048 | BN82: -0.85100001 | BO82: 10.991 | BP82: 2.0210001 | BQ82: 10.458 | BR82: 0.99599999 | BS82: -1.7900001 | BT82: -0.45900002 | BU82: -1.8150001 | BV82: -0.47300002 | BW82: 10.248 | BX82: 0.70300001 | BY82: 10.258 | BZ82: 0.67800003 | CA82: 12.129001 | CB82: 0.48900002 | CC82: 12.183001 | CD82: 0.40300003 | CE82: 1.909 | CF82: 0.164 | CG82: 1.8330001 | CH82: 0.15400001 | CI82: -9.6282272 | CJ82: 6.3112578 | CK82: -6.012393 | CL82: -10.265355
B83: 0.10416667 | C83: -10.825001 | D83: -1.664 | E83: -10.329 | F83: -1.008 | G83: 0.48400003 | H83: -1.733 | I83: 0.53000003 | J83: -1.7980001 | K83: -15.925001 | L83: 2.8430002 | M83: -16.879002 | N83: 1.9170001 | O83: 9.0700006 | P83: -6.7920003 | Q83: 6.2720003 | R83: -7.9040003 | S83: 3.3100002 | T83: 10.342001 | U83: -6.3180003 | V83: 7.7550006 | W83: 0.0020000001 | X83: -0.040000003 | Y83: -7.0540004 | Z83: -0.92300004 | AA83: -12.149 | AB83: 0.266 | AC83: -12.063001 | AD83: 0.32900003 | AE83: 10.896001 | AF83: -1.7320001 | AG83: 17.301001 | AH83: -1.4080001 | AI83: -0.51800001 | AJ83: 1.485 | AK83: -0.45900002 | AL83: 1.5180001 | AM83: 0 | AN83: 0 | AO83: -3.378 | AP83: -0.40200001 | AQ83: 0 | AR83: 0 | AS83: 0.116 | AT83: 0.026000001 | AU83: 2.2720001 | AV83: 0.15300001 | AW83: 2.2570002 | AX83: 0.192 | AY83: 0 | AZ83: 0 | BA83: 2.0550001 | BB83: 1.6625488 | BC83: 14.211 | BD83: 3.8420002 | BE83: 14.340001 | BF83: 3.8540001 | BG83: -12.381001 | BH83: -3.6850002 | BI83: -12.362 | BJ83: -3.7110002 | BK83: -9.9140005 | BL83: -0.69400001 | BM83: -9.8800001 | BN83: -0.68700004 | BO83: 10.76 | BP83: 1.7690001 | BQ83: 10.14 | BR83: 0.75599998 | BS83: -1.7640001 | BT83: -0.44400004 | BU83: -1.7950001 | BV83: -0.44800001 | BW83: 10.055 | BX83: 0.51700002 | BY83: 10.058001 | BZ83: 0.48600003 | CA83: 11.871 | CB83: 0.013 | CC83: 11.931001 | CD83: -0.066 | CE83: 1.8780001 | CF83: 0.14400001 | CG83: 1.8050001 | CH83: 0.132 | CI83: -9.6282272 | CJ83: 6.6161647 | CK83: -6.012393 | CL83: -10.347016
B84: 0.125 | C84: -10.914001 | D84: -1.628 | E84: -10.424001 | F84: -0.94300002 | G84: 0.64000005 | H84: -1.723 | I84: 0.61200005 | J84: -1.7410001 | K84: -16.187 | L84: 2.8640001 | M84: -17.132 | N84: 1.9100001 | O84: 9.5110006 | P84: -6.6670003 | Q84: 6.5710001 | R84: -7.8410006 | S84: 3.6010001 | T84: 10.583 | U84: -6.5770001 | V84: 7.7080002 | W84: 0 | X84: -0.038000003 | Y84: -6.9350004 | Z84: -0.94200003 | AA84: -12.176001 | AB84: 0.35900003 | AC84: -11.995001 | AD84: 0.43900001 | AE84: 11.031 | AF84: -1.7490001 | AG84: 17.390001 | AH84: -1.457 | AI84: -0.59300005 | AJ84: 1.4720001 | AK84: -0.61900002 | AL84: 1.4910001 | AM84: 0 | AN84: 0 | AO84: -3.3570001 | AP84: -0.42000002 | AQ84: 0 | AR84: 0 | AS84: 0.123 | AT84: 0.025 | AU84: 2.263 | AV84: 0.13800001 | AW84: 2.2690001 | AX84: 0.16100001 | AY84: 0 | AZ84: 0 | BA84: 1.8780001 | BB84: 1.6625488 | BC84: 14.211 | BD84: 3.8420002 | BE84: 14.340001 | BF84: 3.8540001 | BG84: -12.381001 | BH84: -3.6850002 | BI84: -12.362 | BJ84: -3.7110002 | BK84: -9.8650007 | BL84: -0.55300003 | BM84: -9.8660002 | BN84: -0.54500002 | BO84: 10.877001 | BP84: 1.664 | BQ84: 10.269 | BR84: 0.64499998 | BS84: -1.7270001 | BT84: -0.41600001 | BU84: -1.7540001 | BV84: -0.43800002 | BW84: 10.005 | BX84: 0.39600003 | BY84: 10.043 | BZ84: 0.35000002 | CA84: 11.966001 | CB84: -0.084000006 | CC84: 12.087001 | CD84: -0.17400001 | CE84: 1.8380001 | CF84: 0.12200001 | CG84: 1.7550001 | CH84: 0.10200001 | CI84: -9.6282272 | CJ84: 6.5511012 | CK84: -6.012393 | CL84: -10.545814
B85: 0.14583333 | C85: -10.945001 | D85: -3.3640001 | E85: -10.516001 | F85: -2.5780001 | G85: 0.91800004 | H85: 0.155 | I85: 1.011 | J85: 0.16700001 | K85: -16.542002 | L85: -1.7650001 | M85: -17.418001 | N85: -3.0280001 | O85: 9.2250004 | P85: -1.8010001 | Q85: 6.3790002 | R85: -2.8770001 | S85: 3.4470003 | T85: 5.4240003 | U85: -6.5060005 | V85: 2.5080001 | W85: 0 | X85: -0.038000003 | Y85: -6.9260001 | Z85: -1.2240001 | AA85: -12.274 | AB85: -2.4870002 | AC85: -12.112 | AD85: -2.3940001 | AE85: 11.392 | AF85: 1.4180001 | AG85: 17.589001 | AH85: 3.5630002 | AI85: -0.96500003 | AJ85: -0.41200003 | AK85: -0.98000002 | AL85: -0.39700001 | AM85: 0 | AN85: 0 | AO85: -3.381 | AP85: -0.405 | AQ85: 0 | AR85: 0 | AS85: 0.12200001 | AT85: 0.031000001 | AU85: 2.2520001 | AV85: 0.147 | AW85: 2.2770002 | AX85: 0.16800001 | AY85: 0 | AZ85: 0 | BA85: 1.988 | BB85: 1.6625488 | BC85: 14.211 | BD85: 3.8420002 | BE85: 14.340001 | BF85: 3.8540001 | BG85: -12.381001 | BH85: -3.6850002 | BI85: -12.362 | BJ85: -3.7110002 | BK85: -9.7180004 | BL85: -0.98800004 | BM85: -9.6880007 | BN85: -0.96400005 | BO85: 10.883 | BP85: 3.4010003 | BQ85: 10.449 | BR85: 2.2980001 | BS85: -1.6910001 | BT85: -0.39100003 | BU85: -1.725 | BV85: -0.39900002 | BW85: 9.8510008 | BX85: 0.84800005 | BY85: 9.8670006 | BZ85: 0.79200006 | CA85: 12.007001 | CB85: 2.3570001 | CC85: 12.119 | CD85: 2.306 | CE85: 1.8100001 | CF85: 0.089000002 | CG85: 1.7190001 | CH85: 0.072000004 | CI85: -9.6282272 | CJ85: 1.6069881 | CK85: -6.012393 | CL85: -5.5302105
B86: 0.16666667 | C86: -12.308001 | D86: -4.5540004 | E86: -11.944 | F86: -3.5780001 | G86: 2.3730001 | H86: 1.434 | I86: 2.4970002 | J86: 1.48 | K86: -19.881001 | L86: -4.5950003 | M86: -20.549002 | N86: -6.1610003 | O86: 13.31 | P86: 2.309 | Q86: 8.9320002 | R86: -0.17600001 | S86: 5.8970003 | T86: 7.2160006 | U86: -8.882 | V86: -0.027000001 | W86: 0.0020000001 | X86: -0.038000003 | Y86: -6.8520002 | Z86: -1.6800001 | AA86: -14.264001 | AB86: -4.5140004 | AC86: -14.131001 | AD86: -4.4500003 | AE86: 13.754001 | AF86: 3.5730002 | AG86: 21.093 | AH86: 7.2890005 | AI86: -2.46 | AJ86: -1.7460001 | AK86: -2.5450001 | AL86: -1.7290001 | AM86: 0 | AN86: 0 | AO86: -3.378 | AP86: -0.43200001 | AQ86: 0 | AR86: 0 | AS86: 0.10700001 | AT86: 0.026000001 | AU86: 2.2520001 | AV86: 0.155 | AW86: 2.2820001 | AX86: 0.177 | AY86: 0 | AZ86: 0 | BA86: 2.003 | BB86: 1.6625488 | BC86: 14.211 | BD86: 3.8420002 | BE86: 14.340001 | BF86: 3.8540001 | BG86: -12.381001 | BH86: -3.6850002 | BI86: -12.362 | BJ86: -3.7110002 | BK86: -9.9460001 | BL86: -1.2520001 | BM86: -9.9550009 | BN86: -1.2570001 | BO86: 12.308001 | BP86: 4.5910001 | BQ86: 11.943 | BR86: 3.2639999 | BS86: -1.6750001 | BT86: -0.347 | BU86: -1.6910001 | BV86: -0.36000001 | BW86: 10.111 | BX86: 1.102 | BY86: 10.142 | BZ86: 1.0810001 | CA86: 13.973001 | CB86: 3.9820001 | CC86: 14.126 | CD86: 3.9800003 | CE86: 1.7720001 | CF86: 0.069000006 | CG86: 1.697 | CH86: 0.059000004 | CI86: -9.6282272 | CJ86: -2.1702852 | CK86: -6.012393 | CL86: -7.278203
...

Sheet DASHBOARD
A1: 1 | B1: 2 | C1: 3 | D1: 4 | E1: 5 | F1: 6 | G1: 7 | H1: 8 | I1: 9 | J1: 10 | K1: 11 | L1: 12 | M1: 13 | N1: 14 | O1: 15 | P1: 16 | Q1: 17 | R1: 18 | S1: 19 | T1: 20 | U1: 21 | V1: 22 | W1: 23 | X1: 24 | Y1: 25 | Z1: 26 | AA1: 27 | AB1: 28 | AC1: 29 | AD1: 30 | AE1: 31 | AF1: 32 | AG1: 33 | AH1: 34 | AI1: 35 | AJ1: 36 | AK1: 37 | AL1: 38 | AM1: 39
A2: 69 | B2: 45740.698 | J2: =HOUR(B2)*60+MINUTE(B2) | K2: =HOUR(B2)*3600+MINUTE(B2)*60+SECOND(B2) | L2: 49.93 | M2: =IF(N2=1,"START","STOP") | N2: 1 | O2: 0 | P2: 1 | Q2: 0
K3: 0 | M3: MySQL Status | N3: Connect | T3: =H4
H4: =MOD(K2,3600)
B5: KIT : TABEL = KIT_REALTIME | R5: 3600 | T5: 0.10069444 | U5: 0.095833333 | V5: 0.099305556
B6: SITE | C6: MKS | F6: TOTAL | G6: =SUM(G9:G87) | I6: 34 sec | M6: BUSBAR : TABEL = SYS_BSBAR | P6: 48 sec | R6: TRANSMISI | X6: LINK | AD6: =K2
B7: U N I T PEMBANGKIT | C7: JENIS_KIT | D7: ID_KIT | E7: ID_UNIT | F7: KEY_ID | G7: Daya Aktif (MW) | H7: Daya Reaktif (MVar) | I7: Daya Total (kVA) | J7: Power Factor | K7: DAYA MAMPU | M7: SITE | N7: TEGANGAN | Q7: RTU LINK | R7: LOKASI | T7: MW | U7: MVAR | V7: I | W7: V | X7: 1 | Z7: RTU LINK | AA7: 2 | AC7: TIME | AD7: =J2
N8: BUSBAR_A | O8: BUSBAR_B | P8: MAX | R8: SITE | S8: LINE | X8: 900 | Z8: VALUE | AA8: 50.5 | AC8: SAMPLING | AD8: 573
A9: 1 | B9: PLTA BAKARU | C9: PLTA | D9: 01 | E9: 01 | F9: =CONCATENATE($C$6,C9,D9,E9) | G9: 62.21 | H9: -2.77 | L9: -6.11 | M9: TELLO5 | N9: 149.4 | O9: 149.58 | P9: =MAX(N9:O9) | Q9: 2 | R9: LASSA5 | S9: KLKSM5-1 | T9: 61.31 | U9: -5.23 | V9: 235.86 | X9: 69.69
A10: 2 | C10: PLTA | D10: 01 | E10: 02 | F10: =CONCATENATE($C$6,C10,D10,E10) | G10: 61.46 | H10: -3.46 | M10: TELLO4 | N10: 0 | O10: 0 | P10: =MAX(N10:O10) | Q10: 2 | S10: KLKSM5-2 | T10: 59.33 | U10: -5.03 | V10: 234.1
A11: 3 | B11: PLTA MALEA | C11: PLTA | D11: 02 | E11: 01 | F11: =CONCATENATE($C$6,C11,D11,E11) | G11: 25.56 | H11: 4.31 | M11: KIMA5 | N11: 150.02 | O11: 0 | P11: =MAX(N11:O11) | Q11: 2 | S11: MLILI5-1 | T11: -64.96 | U11: 3.84 | V11: 251.43
A12: 4 | C12: PLTA | D12: 02 | E12: 02 | F12: =CONCATENATE($C$6,C12,D12,E12) | G12: 25.66 | H12: 4 | L12: testtttt | M12: BSOWA5 | N12: 152.05 | O12: 0 | P12: =MAX(N12:O12) | Q12: 2 | S12: MLILI5-2 | T12: -65.2 | U12: 3.69 | V12: 247.28
A13: 5 | B13: PLTA PAMONA | C13: PLTA | D13: 03 | E13: 01 | F13: =CONCATENATE($C$6,C13,D13,E13) | G13: 39.76 | H13: 4.22 | M13: PNKEP5 | N13: 147.4 | O13: 147.35 | P13: =MAX(N13:O13) | Q13: 2 | S13: TRF52-1 | T13: 8.39 | U13: 2.68 | V13: 0
A14: 6 | C14: PLTA | D14: 03 | E14: 02 | F14: =CONCATENATE($C$6,C14,D14,E14) | G14: 40.74 | H14: 3.77 | M14: PNKEP4 | N14: 67.29 | O14: 65.94 | P14: =MAX(N14:O14) | S14: SPARE
A15: 7 | C15: PLTA | D15: 03 | E15: 03 | F15: =CONCATENATE($C$6,C15,D15,E15) | G15: 38.88 | H15: 3.14 | M15: MAROS5 | N15: 150.91 | O15: 150.6 | P15: =MAX(N15:O15) | Q15: 2 | S15: SPARE
A16: 8 | C16: PLTA | D16: 03 | E16: 04 | F16: =CONCATENATE($C$6,C16,D16,E16) | G16: 32.45 | H16: 2.57 | M16: DAYA5 | N16: 150.69 | O16: 150.78 | P16: =MAX(N16:O16) | Q16: 2 | S16: SPARE
A17: 9 | C17: PLTA | D17: 03 | E17: 05 | F17: =CONCATENATE($C$6,C17,D17,E17) | G17: 39.69 | H17: 3.58 | M17: DAYA4 | N17: 66.99 | O17: 0 | P17: =MAX(N17:O17) | Q17: 2 | R17: KLAKA5 | S17: KLKSM5-1 | T17: -56.36 | U17: 0 | V17: 217.63
A18: 10 | C18: PLTA | D18: 03 | E18: 06 | F18: =CONCATENATE($C$6,C18,D18,E18) | G18: 39.8 | H18: 2.87 | L18: 0 | M18: PKANG5 | N18: 0 | O18: 149.18 | P18: =MAX(N18:O18) | Q18: 2 | S18: KLKSM5-2 | T18: -56.65 | U18: 0 | V18: 220.04
A19: 11 | C19: PLTA | D19: 03 | E19: 07 | F19: =CONCATENATE($C$6,C19,D19,E19) | G19: 45.59 | H19: 5.33 | M19: TLAMA5 | N19: 149.71 | O19: 149.67 | P19: =MAX(N19:O19) | Q19: 2 | S19: UNAHA5-1 | T19: 7.54 | U19: -7.46 | V19: 41.18
A20: 12 | B20: PLTA SULEWANA | C20: PLTA | D20: 04 | E20: 01 | F20: =CONCATENATE($C$6,C20,D20,E20) | G20: 30.24 | H20: 2.85 | M20: MNDAI4 | N20: 66.8 | O20: 68.12 | P20: =MAX(N20:O20) | Q20: 2 | S20: UNAHA5-1 | T20: 7.47 | U20: -7.47 | V20: 41.06
A21: 13 | C21: PLTA | D21: 04 | E21: 02 | F21: =CONCATENATE($C$6,C21,D21,E21) | G21: 26.24 | H21: 3.54 | M21: TNSA34 | N21: 0 | O21: 0 | P21: =MAX(N21:O21) | Q21: 2 | S21: TRF52-1 | T21: 18.12 | U21: 6.78 | V21: 0
A22: 14 | C22: PLTA | D22: 04 | E22: 03 | F22: =CONCATENATE($C$6,C22,D22,E22) | G22: 30.46 | H22: 2.98 | M22: BNTLA4 | N22: 0 | O22: 0 | P22: =MAX(N22:O22) | Q22: 2 | S22: ANTAM5-1 | T22: 39.23 | U22: 4.49 | V22: 157.66
A23: 15 | C23: PLTA | D23: 04 | E23: 04 | F23: =CONCATENATE($C$6,C23,D23,E23) | G23: 30.13 | H23: 3.65 | M23: BNTLA5 | N23: 149.99 | O23: 0 | P23: =MAX(N23:O23) | Q23: 2 | S23: ANTAM5-2 | T23: 40.17 | U23: 4.49 | V23: 157.9
A24: 16 | B24: PLTA BILI BILI | C24: PLTA | D24: 05 | E24: 01 | F24: =CONCATENATE($C$6,C24,D24,E24) | G24: 5.39 | H24: -0.55 | M24: SGMSA5 | N24: 149.98 | O24: 150.45 | P24: =MAX(N24:O24) | Q24: 2 | S24: SPARE
A25: 17 | C25: PLTA | D25: 05 | E25: 02 | F25: =CONCATENATE($C$6,C25,D25,E25) | G25: 10.87 | H25: -2.94 | M25: TBNGA5 | N25: 146.42 | O25: 149.84 | P25: =MAX(N25:O25) | Q25: 2 | R25: KLKSM5 | S25: KLAKA5-1 | T25: 57.81 | U25: -2.21 | V25: 220.36
A26: 18 | B26: PLTA PUNAGAYA | C26: PLTU | D26: 01 | E26: 01 | F26: =CONCATENATE($C$6,C26,D26,E26) | G26: 0 | H26: 1.05 | M26: BLNGI5 | N26: 150.46 | O26: 150.46 | P26: =MAX(N26:O26) | Q26: 2 | S26: KLAKA5-2 | T26: 57.53 | U26: -2.1 | V26: 220.51
A27: 19 | C27: PLTU | D27: 01 | E27: 02 | F27: =CONCATENATE($C$6,C27,D27,E27) | G27: 97.78 | H27: 9.38 | M27: LANNA5 | N27: 152.64 | O27: 0 | P27: =MAX(N27:O27) | Q27: 2 | S27: LASSA5-1 | T27: -58.78 | U27: 3.43 | V27: 229.68
A28: 20 | B28: PLTU JENEPONTO 12 | C28: PLTU | D28: 02 | E28: 01 | F28: =CONCATENATE($C$6,C28,D28,E28) | G28: 55.72 | H28: 9.45 | M28: TLASA5 | N28: 151.91 | O28: 150.38 | P28: =MAX(N28:O28) | Q28: 2 | S28: LASSA5-2 | T28: -59.87 | U28: 2.49 | V28: 227.34
A29: 21 | C29: PLTU | D29: 02 | E29: 02 | F29: =CONCATENATE($C$6,C29,D29,E29) | G29: 0 | H29: 9.4 | M29: PNGYA5 | N29: 151.79 | O29: 151.88 | P29: =MAX(N29:O29) | Q29: 2 | S29: TRF52-1 | T29: 3.14 | U29: 0.8 | V29: 0
A30: 22 | B30: PLTU JENEPONTO 34 | C30: PLTU | D30: 03 | E30: 01 | F30: =CONCATENATE($C$6,C30,D30,E30) | G30: 120.88 | H30: 39.59 | M30: PJNPT1 | N30: 151.57 | O30: 151.57 | P30: =MAX(N30:O30) | Q30: 2 | S30: PTCMP5-1 | T30: 0 | U30: 0 | V30: 3.67
A31: 23 | C31: PLTU | D31: 03 | E31: 02 | F31: =CONCATENATE($C$6,C31,D31,E31) | G31: 121.62 | H31: 64.77 | M31: PJNPT2 | N31: 151.94 | O31: 151.97 | P31: =MAX(N31:O31) | Q31: 2 | S31: PTCMP5-2 | T31: 0 | U31: 0 | V31: 5.4
A32: 24 | B32: PLTU BALUSU | C32: PLTU | D32: 04 | E32: 01 | F32: =CONCATENATE($C$6,C32,D32,E32) | G32: 43.58 | H32: 10.03 | M32: PLTBT | N32: 148.98 | O32: 151 | P32: =MAX(N32:O32) | Q32: 2 | S32: BMPP5-2 | T32: 0 | U32: 0 | V32: 0
A33: 25 | C33: PLTU | D33: 04 | E33: 02 | F33: =CONCATENATE($C$6,C33,D33,E33) | G33: 40.36 | H33: 1.74 | M33: BNTGN5 | N33: 146.45 | O33: 0 | P33: =MAX(N33:O33) | Q33: 2 | R33: PWATU5 | S33: KDNEW5-1 | T33: 15.38 | U33: -6.06 | V33: 65.8
A34: 26 | C34: PLTU | D34: 04 | E34: 03 | F34: =CONCATENATE($C$6,C34,D34,E34) | G34: 96.09 | H34: 15.9 | M34: BNTGS5 | N34: 143.67 | O34: 143.81 | P34: =MAX(N34:O34) | Q34: 2 | S34: KDNEW5-2 | T34: 15.44 | U34: -6.2 | V34: 67.04
A35: 27 | B35: PLTU MORAMO | C35: PLTU | D35: 05 | E35: 01 | F35: =CONCATENATE($C$6,C35,D35,E35) | G35: 49.36 | H35: 0 | M35: BTGSM5 | N35: 143.87 | O35: 144.09 | P35: =MAX(N35:O35) | Q35: 2 | S35: INC45-1 | T35: 15.56 | U35: -5.04 | V35: 151.34
A36: 28 | C36: PLTU | D36: 05 | E36: 02 | F36: =CONCATENATE($C$6,C36,D36,E36) | G36: -0.59 | H36: 21.2 | M36: BKMBA5 | N36: 143.77 | O36: 143.93 | P36: =MAX(N36:O36) | Q36: 2 | S36: INC45-2 | T36: 15.53 | U36: -5.14 | V36: 146.73
A37: 29 | B37: PLTU NII TANASA | C37: PLTU | D37: 06 | E37: 01 | F37: =CONCATENATE($C$6,C37,D37,E37) | G37: 8.57 | H37: 1.2 | M37: TNETE5 | N37: 143.85 | O37: 144.17 | P37: =MAX(N37:O37) | Q37: 2 | S37: SPARE
A38: 30 | C38: PLTU | D38: 06 | E38: 02 | F38: =CONCATENATE($C$6,C38,D38,E38) | G38: 9.67 | H38: 1.05 | M38: SNJAI5 | N38: 143.51 | O38: 144.36 | P38: =MAX(N38:O38) | Q38: 2 | S38: SPARE
A39: 31 | C39: PLTU | D39: 06 | E39: 03 | F39: =CONCATENATE($C$6,C39,D39,E39) | G39: 8.02 | H39: 0 | M39: SPENG5 | N39: 151.18 | O39: 151.14 | P39: =MAX(N39:O39) | Q39: 2 | S39: SPARE
A40: 32 | B40: PLTB TOLO | C40: PLTB | D40: 01 | E40: 01 | F40: =CONCATENATE($C$6,C40,D40,E40) | G40: 11.04 | H40: -0.01 | J40: =G41+G40 | M40: BONE5 | N40: 148.18 | O40: 148.5 | P40: =MAX(N40:O40) | Q40: 2 | R40: UNAHA5 | S40: KDNEW5-1 | T40: -0.61 | U40: -3.62 | V40: 16.13
...

Sheet CONTROL
C1: =DASHBOARD!H4
F3: 27 | G3: 55
B4: POLLING TIME | F4: =F3*60 | G4: =G3*60 | J4: 20230901
B5: GROUP | C5: 30 MIN | D5: 60 MIN | E5: KET | J5: 30 MIN | K5: 60 MIN
B6: KIT_MW_MVAR | C6: 1740 | D6: 3540 | E6: 34 | G6: deviasi | J6: 1770 | K6: 3570 | M6: =J6-10 | N6: =K6-10
B7: BUSBAR_AB | C7: 1100 | D7: 2900 | E7: 50 | G7: =C10-C7 | H7: =D10-D7 | J7: 1780 | K7: 3580 | M7: 1780 | N7: 3580
B8: TRANS_P | C8: 1560 | D8: 3360 | E8: 0.10416667 | F8: 30S | G8: =C6-C8 | H8: =D6-D8 | J8: 1730 | K8: 3530 | M8: =J8-10 | N8: =K8-10
B9: TRANS_Q | C9: 1380 | D9: 3180 | E9: 0.10416667 | G9: =C8-C9 | H9: =D8-D9 | J9: 1750 | K9: 3550 | M9: =J9-10 | N9: =K9-10
B10: TRANS_I | C10: 1200 | D10: 3000 | E10: 0.10416667 | G10: =C9-C10 | H10: =D9-D10 | J10: =J9-120 | K10: =K9-120 | M10: =J10-10 | N10: =K10-10
J11: =J10-120 | K11: =K10-120 | M11: =J11-10 | N11: =K11-10
F12: start from | G12: =C12/60 | H12: min | J12: =J11-120 | K12: =K11-120 | M12: =J12-10 | N12: =K12-10
B13: RTULINK | C13: 1200 | D13: 3100 | F13: and | G13: =D12/60 | H13: min
A15: RTU LINK | B15: 30 | C15: =B15+30 | D15: =C15+30 | E15: =D15+30 | F15: =E15+30 | G15: =F15+30 | H15: =G15+30 | I15: =H15+30 | J15: =I15+30 | ... AV15: =AU15+30 | AW15: =AV15+25
B16: 0.3 | C16: 1 | D16: 1.3 | E16: 2 | F16: 2.3 | G16: 3 | H16: 3.3 | I16: 4 | J16: 4.3 | K16: 5 | L16: 5.3 | M16: 6 | N16: 6.3 | O16: 7 | P16: 7.3 | Q16: 8 | R16: 8.3 | S16: 9 | T16: 9.3 | U16: 10 | V16: 10.3 | W16: 11 | X16: 11.3 | Y16: 12 | Z16: 12.3 | AA16: 13 | AB16: 13.3 | AC16: 14 | AD16: 14.3 | AE16: 15 | AF16: 15.3 | AG16: 16 | AH16: 16.3 | AI16: 17 | AJ16: 17.3 | AK16: 18 | AL16: 18.3 | AM16: 19 | AN16: 19.3 | AO16: 20 | AP16: 20.3 | AQ16: 21 | AR16: 21.3 | AS16: 22 | AT16: 22.3 | AU16: 23 | AV16: 23.3 | AW16: 24 | BA16: 150
A17: TELLO5 | B17: =(IF(DASHBOARD!$J$2=B15,DASHBOARD!$Q$9,IF(DASHBOARD!$J$2=0,0,CONTROL!B17))) | C17: =(IF(DASHBOARD!$J$2=C15,DASHBOARD!$Q$9,IF(DASHBOARD!$J$2=0,0,CONTROL!C17))) | D17: =(IF(DASHBOARD!$J$2=D15,DASHBOARD!$Q$9,IF(DASHBOARD!$J$2=0,0,CONTROL!D17))) | E17: =(IF(DASHBOARD!$J$2=E15,DASHBOARD!$Q$9,IF(DASHBOARD!$J$2=0,0,CONTROL!E17))) | F17: =(IF(DASHBOARD!$J$2=F15,DASHBOARD!$Q$9,IF(DASHBOARD!$J$2=0,0,CONTROL!F17))) | G17: =(IF(DASHBOARD!$J$2=G15,DASHBOARD!$Q$9,IF(DASHBOARD!$J$2=0,0,CONTROL!G17))) | H17: =(IF(DASHBOARD!$J$2=H15,DASHBOARD!$Q$9,IF(DASHBOARD!$J$2=0,0,CONTROL!H17))) | I17: =(IF(DASHBOARD!$J$2=I15,DASHBOARD!$Q$9,IF(DASHBOARD!$J$2=0,0,CONTROL!I17))) | ... AW17: =(IF(DASHBOARD!$J$2=AW15,DASHBOARD!$Q$9,IF(DASHBOARD!$J$2=0,0,CONTROL!AW17))) | AZ17: TELLO5 | BA17: =MATCH(AZ17,A17:B19,0)
A18: TELLO4 | B18: =(IF(DASHBOARD!$J$2=B15,DASHBOARD!$Q$10,IF(DASHBOARD!$J$2=0,0,CONTROL!B18))) | C18: =(IF(DASHBOARD!$J$2=C15,DASHBOARD!$Q$10,IF(DASHBOARD!$J$2=0,0,CONTROL!C18))) | D18: =(IF(DASHBOARD!$J$2=D15,DASHBOARD!$Q$10,IF(DASHBOARD!$J$2=0,0,CONTROL!D18))) | E18: =(IF(DASHBOARD!$J$2=E15,DASHBOARD!$Q$10,IF(DASHBOARD!$J$2=0,0,CONTROL!E18))) | F18: =(IF(DASHBOARD!$J$2=F15,DASHBOARD!$Q$10,IF(DASHBOARD!$J$2=0,0,CONTROL!F18))) | G18: =(IF(DASHBOARD!$J$2=G15,DASHBOARD!$Q$10,IF(DASHBOARD!$J$2=0,0,CONTROL!G18))) | H18: =(IF(DASHBOARD!$J$2=H15,DASHBOARD!$Q$10,IF(DASHBOARD!$J$2=0,0,CONTROL!H18))) | I18: =(IF(DASHBOARD!$J$2=I15,DASHBOARD!$Q$10,IF(DASHBOARD!$J$2=0,0,CONTROL!I18))) | ... AW18: =(IF(DASHBOARD!$J$2=AW15,DASHBOARD!$Q$10,IF(DASHBOARD!$J$2=0,0,CONTROL!AW18))) | AZ18: TELLO4
A19: KIMA5 | B19: =(IF(DASHBOARD!$J$2=B15,DASHBOARD!$Q$11,IF(DASHBOARD!$J$2=0,0,CONTROL!B19))) | C19: =(IF(DASHBOARD!$J$2=C15,DASHBOARD!$Q$11,IF(DASHBOARD!$J$2=0,0,CONTROL!C19))) | D19: =(IF(DASHBOARD!$J$2=D15,DASHBOARD!$Q$11,IF(DASHBOARD!$J$2=0,0,CONTROL!D19))) | E19: =(IF(DASHBOARD!$J$2=E15,DASHBOARD!$Q$11,IF(DASHBOARD!$J$2=0,0,CONTROL!E19))) | F19: =(IF(DASHBOARD!$J$2=F15,DASHBOARD!$Q$11,IF(DASHBOARD!$J$2=0,0,CONTROL!F19))) | G19: =(IF(DASHBOARD!$J$2=G15,DASHBOARD!$Q$11,IF(DASHBOARD!$J$2=0,0,CONTROL!G19))) | H19: =(IF(DASHBOARD!$J$2=H15,DASHBOARD!$Q$11,IF(DASHBOARD!$J$2=0,0,CONTROL!H19))) | I19: =(IF(DASHBOARD!$J$2=I15,DASHBOARD!$Q$11,IF(DASHBOARD!$J$2=0,0,CONTROL!I19))) | ... AW19: =(IF(DASHBOARD!$J$2=AW15,DASHBOARD!$Q$11,IF(DASHBOARD!$J$2=0,0,CONTROL!AW19))) | AZ19: KIMA5
A20: BSOWA5 | B20: =(IF(DASHBOARD!$J$2=B15,DASHBOARD!$Q$12,IF(DASHBOARD!$J$2=0,0,CONTROL!B20))) | C20: =(IF(DASHBOARD!$J$2=C15,DASHBOARD!$Q$12,IF(DASHBOARD!$J$2=0,0,CONTROL!C20))) | D20: =(IF(DASHBOARD!$J$2=D15,DASHBOARD!$Q$12,IF(DASHBOARD!$J$2=0,0,CONTROL!D20))) | E20: =(IF(DASHBOARD!$J$2=E15,DASHBOARD!$Q$12,IF(DASHBOARD!$J$2=0,0,CONTROL!E20))) | F20: =(IF(DASHBOARD!$J$2=F15,DASHBOARD!$Q$12,IF(DASHBOARD!$J$2=0,0,CONTROL!F20))) | G20: =(IF(DASHBOARD!$J$2=G15,DASHBOARD!$Q$12,IF(DASHBOARD!$J$2=0,0,CONTROL!G20))) | H20: =(IF(DASHBOARD!$J$2=H15,DASHBOARD!$Q$12,IF(DASHBOARD!$J$2=0,0,CONTROL!H20))) | I20: =(IF(DASHBOARD!$J$2=I15,DASHBOARD!$Q$12,IF(DASHBOARD!$J$2=0,0,CONTROL!I20))) | ... AW20: =(IF(DASHBOARD!$J$2=AW15,DASHBOARD!$Q$12,IF(DASHBOARD!$J$2=0,0,CONTROL!AW20))) | AZ20: BSOWA5
A21: PNKEP5 | B21: =(IF(DASHBOARD!$J$2=B15,DASHBOARD!$Q$13,IF(DASHBOARD!$J$2=0,0,CONTROL!B21))) | C21: =(IF(DASHBOARD!$J$2=C15,DASHBOARD!$Q$13,IF(DASHBOARD!$J$2=0,0,CONTROL!C21))) | D21: =(IF(DASHBOARD!$J$2=D15,DASHBOARD!$Q$13,IF(DASHBOARD!$J$2=0,0,CONTROL!D21))) | E21: =(IF(DASHBOARD!$J$2=E15,DASHBOARD!$Q$13,IF(DASHBOARD!$J$2=0,0,CONTROL!E21))) | F21: =(IF(DASHBOARD!$J$2=F15,DASHBOARD!$Q$13,IF(DASHBOARD!$J$2=0,0,CONTROL!F21))) | G21: =(IF(DASHBOARD!$J$2=G15,DASHBOARD!$Q$13,IF(DASHBOARD!$J$2=0,0,CONTROL!G21))) | H21: =(IF(DASHBOARD!$J$2=H15,DASHBOARD!$Q$13,IF(DASHBOARD!$J$2=0,0,CONTROL!H21))) | I21: =(IF(DASHBOARD!$J$2=I15,DASHBOARD!$Q$13,IF(DASHBOARD!$J$2=0,0,CONTROL!I21))) | ... AW21: =(IF(DASHBOARD!$J$2=AW15,DASHBOARD!$Q$13,IF(DASHBOARD!$J$2=0,0,CONTROL!AW21))) | AZ21: PNKEP5
A22: MAROS5 | B22: =(IF(DASHBOARD!$J$2=B15,DASHBOARD!$Q$15,IF(DASHBOARD!$J$2=0,0,CONTROL!B22))) | C22: =(IF(DASHBOARD!$J$2=C15,DASHBOARD!$Q$15,IF(DASHBOARD!$J$2=0,0,CONTROL!C22))) | D22: =(IF(DASHBOARD!$J$2=D15,DASHBOARD!$Q$15,IF(DASHBOARD!$J$2=0,0,CONTROL!D22))) | E22: =(IF(DASHBOARD!$J$2=E15,DASHBOARD!$Q$15,IF(DASHBOARD!$J$2=0,0,CONTROL!E22))) | F22: =(IF(DASHBOARD!$J$2=F15,DASHBOARD!$Q$15,IF(DASHBOARD!$J$2=0,0,CONTROL!F22))) | G22: =(IF(DASHBOARD!$J$2=G15,DASHBOARD!$Q$15,IF(DASHBOARD!$J$2=0,0,CONTROL!G22))) | H22: =(IF(DASHBOARD!$J$2=H15,DASHBOARD!$Q$15,IF(DASHBOARD!$J$2=0,0,CONTROL!H22))) | I22: =(IF(DASHBOARD!$J$2=I15,DASHBOARD!$Q$15,IF(DASHBOARD!$J$2=0,0,CONTROL!I22))) | ... AW22: =(IF(DASHBOARD!$J$2=AW15,DASHBOARD!$Q$15,IF(DASHBOARD!$J$2=0,0,CONTROL!AW22))) | AZ22: MAROS5
A23: DAYA5 | B23: =(IF(DASHBOARD!$J$2=B15,DASHBOARD!$Q$16,IF(DASHBOARD!$J$2=0,0,CONTROL!B23))) | C23: =(IF(DASHBOARD!$J$2=C15,DASHBOARD!$Q$16,IF(DASHBOARD!$J$2=0,0,CONTROL!C23))) | D23: =(IF(DASHBOARD!$J$2=D15,DASHBOARD!$Q$16,IF(DASHBOARD!$J$2=0,0,CONTROL!D23))) | E23: =(IF(DASHBOARD!$J$2=E15,DASHBOARD!$Q$16,IF(DASHBOARD!$J$2=0,0,CONTROL!E23))) | F23: =(IF(DASHBOARD!$J$2=F15,DASHBOARD!$Q$16,IF(DASHBOARD!$J$2=0,0,CONTROL!F23))) | G23: =(IF(DASHBOARD!$J$2=G15,DASHBOARD!$Q$16,IF(DASHBOARD!$J$2=0,0,CONTROL!G23))) | H23: =(IF(DASHBOARD!$J$2=H15,DASHBOARD!$Q$16,IF(DASHBOARD!$J$2=0,0,CONTROL!H23))) | I23: =(IF(DASHBOARD!$J$2=I15,DASHBOARD!$Q$16,IF(DASHBOARD!$J$2=0,0,CONTROL!I23))) | ... AW23: =(IF(DASHBOARD!$J$2=AW15,DASHBOARD!$Q$16,IF(DASHBOARD!$J$2=0,0,CONTROL!AW23))) | AZ23: DAYA5
A24: DAYA4 | B24: =(IF(DASHBOARD!$J$2=B15,DASHBOARD!$Q$17,IF(DASHBOARD!$J$2=0,0,CONTROL!B24))) | C24: =(IF(DASHBOARD!$J$2=C15,DASHBOARD!$Q$17,IF(DASHBOARD!$J$2=0,0,CONTROL!C24))) | D24: =(IF(DASHBOARD!$J$2=D15,DASHBOARD!$Q$17,IF(DASHBOARD!$J$2=0,0,CONTROL!D24))) | E24: =(IF(DASHBOARD!$J$2=E15,DASHBOARD!$Q$17,IF(DASHBOARD!$J$2=0,0,CONTROL!E24))) | F24: =(IF(DASHBOARD!$J$2=F15,DASHBOARD!$Q$17,IF(DASHBOARD!$J$2=0,0,CONTROL!F24))) | G24: =(IF(DASHBOARD!$J$2=G15,DASHBOARD!$Q$17,IF(DASHBOARD!$J$2=0,0,CONTROL!G24))) | H24: =(IF(DASHBOARD!$J$2=H15,DASHBOARD!$Q$17,IF(DASHBOARD!$J$2=0,0,CONTROL!H24))) | I24: =(IF(DASHBOARD!$J$2=I15,DASHBOARD!$Q$17,IF(DASHBOARD!$J$2=0,0,CONTROL!I24))) | ... AW24: =(IF(DASHBOARD!$J$2=AW15,DASHBOARD!$Q$17,IF(DASHBOARD!$J$2=0,0,CONTROL!AW24))) | AZ24: DAYA4
A25: PKANG5 | B25: =(IF(DASHBOARD!$J$2=B15,DASHBOARD!$Q$18,IF(DASHBOARD!$J$2=0,0,CONTROL!B25))) | C25: =(IF(DASHBOARD!$J$2=C15,DASHBOARD!$Q$18,IF(DASHBOARD!$J$2=0,0,CONTROL!C25))) | D25: =(IF(DASHBOARD!$J$2=D15,DASHBOARD!$Q$18,IF(DASHBOARD!$J$2=0,0,CONTROL!D25))) | E25: =(IF(DASHBOARD!$J$2=E15,DASHBOARD!$Q$18,IF(DASHBOARD!$J$2=0,0,CONTROL!E25))) | F25: =(IF(DASHBOARD!$J$2=F15,DASHBOARD!$Q$18,IF(DASHBOARD!$J$2=0,0,CONTROL!F25))) | G25: =(IF(DASHBOARD!$J$2=G15,DASHBOARD!$Q$18,IF(DASHBOARD!$J$2=0,0,CONTROL!G25))) | H25: =(IF(DASHBOARD!$J$2=H15,DASHBOARD!$Q$18,IF(DASHBOARD!$J$2=0,0,CONTROL!H25))) | I25: =(IF(DASHBOARD!$J$2=I15,DASHBOARD!$Q$18,IF(DASHBOARD!$J$2=0,0,CONTROL!I25))) | ... AW25: =(IF(DASHBOARD!$J$2=AW15,DASHBOARD!$Q$18,IF(DASHBOARD!$J$2=0,0,CONTROL!AW25))) | AZ25: PKANG5
A26: TLAMA5 | B26: =(IF(DASHBOARD!$J$2=B15,DASHBOARD!$Q$19,IF(DASHBOARD!$J$2=0,0,CONTROL!B26))) | C26: =(IF(DASHBOARD!$J$2=C15,DASHBOARD!$Q$19,IF(DASHBOARD!$J$2=0,0,CONTROL!C26))) | D26: =(IF(DASHBOARD!$J$2=D15,DASHBOARD!$Q$19,IF(DASHBOARD!$J$2=0,0,CONTROL!D26))) | E26: =(IF(DASHBOARD!$J$2=E15,DASHBOARD!$Q$19,IF(DASHBOARD!$J$2=0,0,CONTROL!E26))) | F26: =(IF(DASHBOARD!$J$2=F15,DASHBOARD!$Q$19,IF(DASHBOARD!$J$2=0,0,CONTROL!F26))) | G26: =(IF(DASHBOARD!$J$2=G15,DASHBOARD!$Q$19,IF(DASHBOARD!$J$2=0,0,CONTROL!G26))) | H26: =(IF(DASHBOARD!$J$2=H15,DASHBOARD!$Q$19,IF(DASHBOARD!$J$2=0,0,CONTROL!H26))) | I26: =(IF(DASHBOARD!$J$2=I15,DASHBOARD!$Q$19,IF(DASHBOARD!$J$2=0,0,CONTROL!I26))) | ... AW26: =(IF(DASHBOARD!$J$2=AW15,DASHBOARD!$Q$19,IF(DASHBOARD!$J$2=0,0,CONTROL!AW26))) | AZ26: TLAMA5
A27: MNDAI4 | B27: =(IF(DASHBOARD!$J$2=B15,DASHBOARD!$Q$20,IF(DASHBOARD!$J$2=0,0,CONTROL!B27))) | C27: =(IF(DASHBOARD!$J$2=C15,DASHBOARD!$Q$20,IF(DASHBOARD!$J$2=0,0,CONTROL!C27))) | D27: =(IF(DASHBOARD!$J$2=D15,DASHBOARD!$Q$20,IF(DASHBOARD!$J$2=0,0,CONTROL!D27))) | E27: =(IF(DASHBOARD!$J$2=E15,DASHBOARD!$Q$20,IF(DASHBOARD!$J$2=0,0,CONTROL!E27))) | F27: =(IF(DASHBOARD!$J$2=F15,DASHBOARD!$Q$20,IF(DASHBOARD!$J$2=0,0,CONTROL!F27))) | G27: =(IF(DASHBOARD!$J$2=G15,DASHBOARD!$Q$20,IF(DASHBOARD!$J$2=0,0,CONTROL!G27))) | H27: =(IF(DASHBOARD!$J$2=H15,DASHBOARD!$Q$20,IF(DASHBOARD!$J$2=0,0,CONTROL!H27))) | I27: =(IF(DASHBOARD!$J$2=I15,DASHBOARD!$Q$20,IF(DASHBOARD!$J$2=0,0,CONTROL!I27))) | ... AW27: =(IF(DASHBOARD!$J$2=AW15,DASHBOARD!$Q$20,IF(DASHBOARD!$J$2=0,0,CONTROL!AW27))) | AZ27: MNDAI4
A28: TNSA34 | B28: =(IF(DASHBOARD!$J$2=B15,DASHBOARD!$Q$21,IF(DASHBOARD!$J$2=0,0,CONTROL!B28))) | C28: =(IF(DASHBOARD!$J$2=C15,DASHBOARD!$Q$21,IF(DASHBOARD!$J$2=0,0,CONTROL!C28))) | D28: =(IF(DASHBOARD!$J$2=D15,DASHBOARD!$Q$21,IF(DASHBOARD!$J$2=0,0,CONTROL!D28))) | E28: =(IF(DASHBOARD!$J$2=E15,DASHBOARD!$Q$21,IF(DASHBOARD!$J$2=0,0,CONTROL!E28))) | F28: =(IF(DASHBOARD!$J$2=F15,DASHBOARD!$Q$21,IF(DASHBOARD!$J$2=0,0,CONTROL!F28))) | G28: =(IF(DASHBOARD!$J$2=G15,DASHBOARD!$Q$21,IF(DASHBOARD!$J$2=0,0,CONTROL!G28))) | H28: =(IF(DASHBOARD!$J$2=H15,DASHBOARD!$Q$21,IF(DASHBOARD!$J$2=0,0,CONTROL!H28))) | I28: =(IF(DASHBOARD!$J$2=I15,DASHBOARD!$Q$21,IF(DASHBOARD!$J$2=0,0,CONTROL!I28))) | ... AW28: =(IF(DASHBOARD!$J$2=AW15,DASHBOARD!$Q$21,IF(DASHBOARD!$J$2=0,0,CONTROL!AW28))) | AZ28: TNSA34
A29: BNTLA4 | B29: =(IF(DASHBOARD!$J$2=B15,DASHBOARD!$Q$22,IF(DASHBOARD!$J$2=0,0,CONTROL!B29))) | C29: =(IF(DASHBOARD!$J$2=C15,DASHBOARD!$Q$22,IF(DASHBOARD!$J$2=0,0,CONTROL!C29))) | D29: =(IF(DASHBOARD!$J$2=D15,DASHBOARD!$Q$22,IF(DASHBOARD!$J$2=0,0,CONTROL!D29))) | E29: =(IF(DASHBOARD!$J$2=E15,DASHBOARD!$Q$22,IF(DASHBOARD!$J$2=0,0,CONTROL!E29))) | F29: =(IF(DASHBOARD!$J$2=F15,DASHBOARD!$Q$22,IF(DASHBOARD!$J$2=0,0,CONTROL!F29))) | G29: =(IF(DASHBOARD!$J$2=G15,DASHBOARD!$Q$22,IF(DASHBOARD!$J$2=0,0,CONTROL!G29))) | H29: =(IF(DASHBOARD!$J$2=H15,DASHBOARD!$Q$22,IF(DASHBOARD!$J$2=0,0,CONTROL!H29))) | I29: =(IF(DASHBOARD!$J$2=I15,DASHBOARD!$Q$22,IF(DASHBOARD!$J$2=0,0,CONTROL!I29))) | ... AW29: =(IF(DASHBOARD!$J$2=AW15,DASHBOARD!$Q$22,IF(DASHBOARD!$J$2=0,0,CONTROL!AW29))) | AZ29: BNTLA4
